Workbook

Sheet 空间邻接矩阵
B1: 北京 | C1: 天津 | D1: 河北 | E1: 山西 | F1: 内蒙古 | G1: 辽宁 | H1: 吉林 | I1: 黑龙江 | J1: 上海 | K1: 江苏 | L1: 浙江 | M1: 安徽 | N1: 福建 | O1: 江西 | P1: 山东 | Q1: 河南 | R1: 湖北 | S1: 湖南 | T1: 广东 | U1: 广西 | V1: 海南 | W1: 重庆 | X1: 四川 | Y1: 贵州 | Z1: 云南 | AA1: 西藏 | AB1: 陕西 | AC1: 甘肃 | AD1: 青海 | AE1: 宁夏 | AF1: 新疆
A2: 北京 | B2: 0 | C2: 1 | D2: 1 | E2: 0 | F2: 0 | G2: 0 | H2: 0 | I2: 0 | J2: 0 | K2: 0 | L2: 0 | M2: 0 | N2: 0 | O2: 0 | P2: 0 | Q2: 0 | R2: 0 | S2: 0 | T2: 0 | U2: 0 | V2: 0 | W2: 0 | X2: 0 | Y2: 0 | Z2: 0 | AA2: 0 | AB2: 0 | AC2: 0 | AD2: 0 | AE2: 0 | AF2: 0
A3: 天津 | B3: 1 | C3: 0 | D3: 1 | E3: 0 | F3: 0 | G3: 0 | H3: 0 | I3: 0 | J3: 0 | K3: 0 | L3: 0 | M3: 0 | N3: 0 | O3: 0 | P3: 0 | Q3: 0 | R3: 0 | S3: 0 | T3: 0 | U3: 0 | V3: 0 | W3: 0 | X3: 0 | Y3: 0 | Z3: 0 | AA3: 0 | AB3: 0 | AC3: 0 | AD3: 0 | AE3: 0 | AF3: 0
A4: 河北 | B4: 1 | C4: 1 | D4: 0 | E4: 1 | F4: 1 | G4: 1 | H4: 0 | I4: 0 | J4: 0 | K4: 0 | L4: 0 | M4: 0 | N4: 0 | O4: 0 | P4: 1 | Q4: 1 | R4: 0 | S4: 0 | T4: 0 | U4: 0 | V4: 0 | W4: 0 | X4: 0 | Y4: 0 | Z4: 0 | AA4: 0 | AB4: 0 | AC4: 0 | AD4: 0 | AE4: 0 | AF4: 0
A5: 山西 | B5: 0 | C5: 0 | D5: 1 | E5: 0 | F5: 1 | G5: 0 | H5: 0 | I5: 0 | J5: 0 | K5: 0 | L5: 0 | M5: 0 | N5: 0 | O5: 0 | P5: 0 | Q5: 1 | R5: 0 | S5: 0 | T5: 0 | U5: 0 | V5: 0 | W5: 0 | X5: 0 | Y5: 0 | Z5: 0 | AA5: 0 | AB5: 1 | AC5: 0 | AD5: 0 | AE5: 0 | AF5: 0
A6: 内蒙古 | B6: 0 | C6: 0 | D6: 1 | E6: 1 | F6: 0 | G6: 1 | H6: 1 | I6: 1 | J6: 0 | K6: 0 | L6: 0 | M6: 0 | N6: 0 | O6: 0 | P6: 0 | Q6: 0 | R6: 0 | S6: 0 | T6: 0 | U6: 0 | V6: 0 | W6: 0 | X6: 0 | Y6: 0 | Z6: 0 | AA6: 0 | AB6: 1 | AC6: 1 | AD6: 0 | AE6: 1 | AF6: 0
A7: 辽宁 | B7: 0 | C7: 0 | D7: 1 | E7: 0 | F7: 1 | G7: 0 | H7: 1 | I7: 0 | J7: 0 | K7: 0 | L7: 0 | M7: 0 | N7: 0 | O7: 0 | P7: 0 | Q7: 0 | R7: 0 | S7: 0 | T7: 0 | U7: 0 | V7: 0 | W7: 0 | X7: 0 | Y7: 0 | Z7: 0 | AA7: 0 | AB7: 0 | AC7: 0 | AD7: 0 | AE7: 0 | AF7: 0
A8: 吉林 | B8: 0 | C8: 0 | D8: 0 | E8: 0 | F8: 1 | G8: 1 | H8: 0 | I8: 1 | J8: 0 | K8: 0 | L8: 0 | M8: 0 | N8: 0 | O8: 0 | P8: 0 | Q8: 0 | R8: 0 | S8: 0 | T8: 0 | U8: 0 | V8: 0 | W8: 0 | X8: 0 | Y8: 0 | Z8: 0 | AA8: 0 | AB8: 0 | AC8: 0 | AD8: 0 | AE8: 0 | AF8: 0
A9: 黑龙江 | B9: 0 | C9: 0 | D9: 0 | E9: 0 | F9: 1 | G9: 0 | H9: 1 | I9: 0 | J9: 0 | K9: 0 | L9: 0 | M9: 0 | N9: 0 | O9: 0 | P9: 0 | Q9: 0 | R9: 0 | S9: 0 | T9: 0 | U9: 0 | V9: 0 | W9: 0 | X9: 0 | Y9: 0 | Z9: 0 | AA9: 0 | AB9: 0 | AC9: 0 | AD9: 0 | AE9: 0 | AF9: 0
A10: 上海 | B10: 0 | C10: 0 | D10: 0 | E10: 0 | F10: 0 | G10: 0 | H10: 0 | I10: 0 | J10: 0 | K10: 1 | L10: 1 | M10: 0 | N10: 0 | O10: 0 | P10: 0 | Q10: 0 | R10: 0 | S10: 0 | T10: 0 | U10: 0 | V10: 0 | W10: 0 | X10: 0 | Y10: 0 | Z10: 0 | AA10: 0 | AB10: 0 | AC10: 0 | AD10: 0 | AE10: 0 | AF10: 0
A11: 江苏 | B11: 0 | C11: 0 | D11: 0 | E11: 0 | F11: 0 | G11: 0 | H11: 0 | I11: 0 | J11: 1 | K11: 0 | L11: 1 | M11: 1 | N11: 0 | O11: 0 | P11: 1 | Q11: 0 | R11: 0 | S11: 0 | T11: 0 | U11: 0 | V11: 0 | W11: 0 | X11: 0 | Y11: 0 | Z11: 0 | AA11: 0 | AB11: 0 | AC11: 0 | AD11: 0 | AE11: 0 | AF11: 0
A12: 浙江 | B12: 0 | C12: 0 | D12: 0 | E12: 0 | F12: 0 | G12: 0 | H12: 0 | I12: 0 | J12: 1 | K12: 1 | L12: 0 | M12: 1 | N12: 1 | O12: 1 | P12: 0 | Q12: 0 | R12: 0 | S12: 0 | T12: 0 | U12: 0 | V12: 0 | W12: 0 | X12: 0 | Y12: 0 | Z12: 0 | AA12: 0 | AB12: 0 | AC12: 0 | AD12: 0 | AE12: 0 | AF12: 0
A13: 安徽 | B13: 0 | C13: 0 | D13: 0 | E13: 0 | F13: 0 | G13: 0 | H13: 0 | I13: 0 | J13: 0 | K13: 1 | L13: 1 | M13: 0 | N13: 0 | O13: 1 | P13: 1 | Q13: 1 | R13: 1 | S13: 0 | T13: 0 | U13: 0 | V13: 0 | W13: 0 | X13: 0 | Y13: 0 | Z13: 0 | AA13: 0 | AB13: 0 | AC13: 0 | AD13: 0 | AE13: 0 | AF13: 0
... A32: 新疆 | B32: 0 | C32: 0 | D32: 0 | E32: 0 | F32: 0 | G32: 0 | H32: 0 | I32: 0 | J32: 0 | K32: 0 | L32: 0 | M32: 0 | N32: 0 | O32: 0 | P32: 0 | Q32: 0 | R32: 0 | S32: 0 | T32: 0 | U32: 0 | V32: 0 | W32: 0 | X32: 0 | Y32: 0 | Z32: 0 | AA32: 1 | AB32: 0 | AC32: 1 | AD32: 1 | AE32: 0 | AF32: 0

Sheet 空间经济地理权重矩阵（经纬度和GDP）
A1: 2000-2020年人均GDP差值 | E1: 北京 | F1: 天津 | G1: 河北 | H1: 山西 | I1: 内蒙古 | J1: 辽宁 | K1: 吉林 | L1: 黑龙江 | M1: 上海 | N1: 江苏 | O1: 浙江 | P1: 安徽 | Q1: 福建 | R1: 江西 | S1: 山东 | T1: 河南 | U1: 湖北 | V1: 湖南 | W1: 广东 | X1: 广西 | Y1: 海南 | Z1: 重庆 | AA1: 四川 | AB1: 贵州 | AC1: 云南 | AD1: 西藏 | AE1: 陕西 | AF1: 甘肃 | AG1: 青海 | AH1: 宁夏 | AI1: 新疆
C2: 对称 | E2: 8.0755955 | F2: 7.0052086 | G2: 2.8453065 | H2: 2.5439215 | I2: 4.2731525 | J2: 3.9071957 | K2: 3.1542437 | L2: 2.6824684 | M2: 8.4268583 | N2: 5.9095777 | O2: 5.4787163 | P2: 2.4864434 | Q2: 4.7187197 | R2: 2.459903 | S2: 4.2175162 | T2: 2.6759095 | U2: 3.3424132 | V2: 2.7958168 | W2: 4.792491 | X2: 2.2252832 | Y2: 2.7189891 | Z2: 3.3299924 | AA2: 2.4972705 | AB2: 1.8439877 | AC2: 2.0072418 | AD2: 2.1829651 | AE2: 3.0830648 | AF2: 1.7444562 | AG2: 2.5986712 | AH2: 2.8062147 | AI2: 2.7600586
A3: 2000-2020 | B3: 8.0755955 | D3: 北京 | E3: =$B3-E$2 -> 0 | F3: =$B3-F$2 -> 1.0703869 | G3: =$B3-G$2 -> 5.230289 | H3: =$B3-H$2 -> 5.531674 | I3: =$B3-I$2 -> 3.802443 | J3: =$B3-J$2 -> 4.1683998 | K3: =$B3-K$2 -> 4.9213518 | L3: =$B3-L$2 -> 5.393127 | ... AI3: =$B3-AI$2 -> 5.3155369
A4: 2000-2020 | B4: 7.0052086 | D4: 天津 | E4: =$B4-E$2 -> -1.0703869 | F4: =$B4-F$2 -> 0 | G4: =$B4-G$2 -> 4.1599021 | H4: =$B4-H$2 -> 4.4612871 | I4: =$B4-I$2 -> 2.7320561 | J4: =$B4-J$2 -> 3.0980129 | K4: =$B4-K$2 -> 3.8509649 | L4: =$B4-L$2 -> 4.3227402 | ... AI4: =$B4-AI$2 -> 4.24515
A5: 2000-2020 | B5: 2.8453065 | D5: 河北 | E5: =$B5-E$2 -> -5.230289 | F5: =$B5-F$2 -> -4.1599021 | G5: =$B5-G$2 -> 0 | H5: =$B5-H$2 -> 0.30138501 | I5: =$B5-I$2 -> -1.427846 | J5: =$B5-J$2 -> -1.0618892 | K5: =$B5-K$2 -> -0.3089372 | L5: =$B5-L$2 -> 0.16283808 | ... AI5: =$B5-AI$2 -> 0.0852479
A6: 2000-2020 | B6: 2.5439215 | D6: 山西 | E6: =$B6-E$2 -> -5.531674 | F6: =$B6-F$2 -> -4.4612871 | G6: =$B6-G$2 -> -0.30138501 | H6: =$B6-H$2 -> 0 | I6: =$B6-I$2 -> -1.729231 | J6: =$B6-J$2 -> -1.3632742 | K6: =$B6-K$2 -> -0.61032221 | L6: =$B6-L$2 -> -0.13854693 | ... AI6: =$B6-AI$2 -> -0.21613711
A7: 2000-2020 | B7: 4.2731525 | D7: 内蒙古 | E7: =$B7-E$2 -> -3.802443 | F7: =$B7-F$2 -> -2.7320561 | G7: =$B7-G$2 -> 1.427846 | H7: =$B7-H$2 -> 1.729231 | I7: =$B7-I$2 -> 0 | J7: =$B7-J$2 -> 0.36595683 | K7: =$B7-K$2 -> 1.1189088 | L7: =$B7-L$2 -> 1.5906841 | ... AI7: =$B7-AI$2 -> 1.5130939
A8: 2000-2020 | B8: 3.9071957 | D8: 辽宁 | E8: =$B8-E$2 -> -4.1683998 | F8: =$B8-F$2 -> -3.0980129 | G8: =$B8-G$2 -> 1.0618892 | H8: =$B8-H$2 -> 1.3632742 | I8: =$B8-I$2 -> -0.36595683 | J8: =$B8-J$2 -> 0 | K8: =$B8-K$2 -> 0.75295197 | L8: =$B8-L$2 -> 1.2247273 | ... AI8: =$B8-AI$2 -> 1.1471371
A9: 2000-2020 | B9: 3.1542437 | D9: 吉林 | E9: =$B9-E$2 -> -4.9213518 | F9: =$B9-F$2 -> -3.8509649 | G9: =$B9-G$2 -> 0.3089372 | H9: =$B9-H$2 -> 0.61032221 | I9: =$B9-I$2 -> -1.1189088 | J9: =$B9-J$2 -> -0.75295197 | K9: =$B9-K$2 -> 0 | L9: =$B9-L$2 -> 0.47177528 | ... AI9: =$B9-AI$2 -> 0.3941851
A10: 2000-2020 | B10: 2.6824684 | D10: 黑龙江 | E10: =$B10-E$2 -> -5.393127 | F10: =$B10-F$2 -> -4.3227402 | G10: =$B10-G$2 -> -0.16283808 | H10: =$B10-H$2 -> 0.13854693 | I10: =$B10-I$2 -> -1.5906841 | J10: =$B10-J$2 -> -1.2247273 | K10: =$B10-K$2 -> -0.47177528 | L10: =$B10-L$2 -> 0 | ... AI10: =$B10-AI$2 -> -0.077590183
A11: 2000-2020 | B11: 8.4268583 | D11: 上海 | E11: =$B11-E$2 -> 0.35126279 | F11: =$B11-F$2 -> 1.4216497 | G11: =$B11-G$2 -> 5.5815518 | H11: =$B11-H$2 -> 5.8829368 | I11: =$B11-I$2 -> 4.1537058 | J11: =$B11-J$2 -> 4.5196626 | K11: =$B11-K$2 -> 5.2726146 | L11: =$B11-L$2 -> 5.7443898 | ... AI11: =$B11-AI$2 -> 5.6667997
A12: 2000-2020 | B12: 5.9095777 | D12: 江苏 | E12: =$B12-E$2 -> -2.1660177 | F12: =$B12-F$2 -> -1.0956308 | G12: =$B12-G$2 -> 3.0642712 | H12: =$B12-H$2 -> 3.3656562 | I12: =$B12-I$2 -> 1.6364252 | J12: =$B12-J$2 -> 2.0023821 | K12: =$B12-K$2 -> 2.755334 | L12: =$B12-L$2 -> 3.2271093 | ... AI12: =$B12-AI$2 -> 3.1495191
A13: 2000-2020 | B13: 5.4787163 | D13: 浙江 | E13: =$B13-E$2 -> -2.5968792 | F13: =$B13-F$2 -> -1.5264923 | G13: =$B13-G$2 -> 2.6334098 | H13: =$B13-H$2 -> 2.9347948 | I13: =$B13-I$2 -> 1.2055638 | J13: =$B13-J$2 -> 1.5715206 | K13: =$B13-K$2 -> 2.3244726 | L13: =$B13-L$2 -> 2.7962479 | ... AI13: =$B13-AI$2 -> 2.7186577
A14: 2000-2020 | B14: 2.4864434 | D14: 安徽 | E14: =$B14-E$2 -> -5.589152 | F14: =$B14-F$2 -> -4.5187651 | G14: =$B14-G$2 -> -0.35886307 | H14: =$B14-H$2 -> -0.057478062 | I14: =$B14-I$2 -> -1.7867091 | J14: =$B14-J$2 -> -1.4207522 | K14: =$B14-K$2 -> -0.66780027 | L14: =$B14-L$2 -> -0.19602499 | ... AI14: =$B14-AI$2 -> -0.27361517
... A33: 2000-2020 | B33: 2.7600586 | D33: 新疆 | E33: =$B33-E$2 -> -5.3155369 | F33: =$B33-F$2 -> -4.24515 | G33: =$B33-G$2 -> -0.0852479 | H33: =$B33-H$2 -> 0.21613711 | I33: =$B33-I$2 -> -1.5130939 | J33: =$B33-J$2 -> -1.1471371 | K33: =$B33-K$2 -> -0.3941851 | L33: =$B33-L$2 -> 0.077590183 | ... AI33: =$B33-AI$2 -> 0
B35: 1/绝对值 | E35: 北京 | F35: 天津 | G35: 河北 | H35: 山西 | I35: 内蒙古 | J35: 辽宁 | K35: 吉林 | L35: 黑龙江 | M35: 上海 | N35: 江苏 | O35: 浙江 | P35: 安徽 | Q35: 福建 | R35: 江西 | S35: 山东 | T35: 河南 | U35: 湖北 | V35: 湖南 | W35: 广东 | X35: 广西 | Y35: 海南 | Z35: 重庆 | AA35: 四川 | AB35: 贵州 | AC35: 云南 | AD35: 西藏 | AE35: 陕西 | AF35: 甘肃 | AG35: 青海 | AH35: 宁夏 | AI35: 新疆
B36: 对称 | D36: 北京 | E36: 0 | F36: =1/ABS(F3) -> 0.93424164 | G36: =1/ABS(G3) -> 0.19119403 | H36: =1/ABS(H3) -> 0.1807771 | I36: =1/ABS(I3) -> 0.26298882 | J36: =1/ABS(J3) -> 0.23990021 | K36: =1/ABS(K3) -> 0.2031962 | L36: =1/ABS(L3) -> 0.18542118 | M36: =1/ABS(M3) -> 2.8468714 | ... AI36: =1/ABS(AI3) -> 0.18812775 | AJ36: =SUM(E36:AI36) -> 9.8571941 | AK36: 9.8571941 | AL36: 9.8571941 | AM36: 9.8571941 | AN36: 9.8571941 | AO36: 9.8571941 | AP36: 9.8571941 | AQ36: 9.8571941 | AR36: 9.8571941 | AS36: 9.8571941 | AT36: 9.8571941 | AU36: 9.8571941 | AV36: 9.8571941 | AW36: 9.8571941 | AX36: 9.8571941 | AY36: 9.8571941 | AZ36: 9.8571941 | BA36: 9.8571941 | BB36: 9.8571941 | BC36: 9.8571941 | BD36: 9.8571941 | BE36: 9.8571941 | BF36: 9.8571941 | BG36: 9.8571941 | BH36: 9.8571941 | BI36: 9.8571941 | BJ36: 9.8571941 | BK36: 9.8571941 | BL36: 9.8571941 | BM36: 9.8571941 | BN36: 9.8571941
D37: 天津 | E37: =1/ABS(E4) -> 0.93424164 | F37: 0 | G37: =1/ABS(G4) -> 0.24039027 | H37: =1/ABS(H4) -> 0.22415056 | I37: =1/ABS(I4) -> 0.3660247 | J37: =1/ABS(J4) -> 0.32278755 | K37: =1/ABS(K4) -> 0.25967518 | L37: =1/ABS(L4) -> 0.23133475 | M37: =1/ABS(M4) -> 0.70340817 | N37: =1/ABS(N4) -> 0.91271618 | ... AI37: =1/ABS(AI4) -> 0.23556294 | AJ37: =SUM(E37:AI37) -> 9.9640449 | AK37: 9.9640449 | AL37: 9.9640449 | AM37: 9.9640449 | AN37: 9.9640449 | AO37: 9.9640449 | AP37: 9.9640449 | AQ37: 9.9640449 | AR37: 9.9640449 | AS37: 9.9640449 | AT37: 9.9640449 | AU37: 9.9640449 | AV37: 9.9640449 | AW37: 9.9640449 | AX37: 9.9640449 | AY37: 9.9640449 | AZ37: 9.9640449 | BA37: 9.9640449 | BB37: 9.9640449 | BC37: 9.9640449 | BD37: 9.9640449 | BE37: 9.9640449 | BF37: 9.9640449 | BG37: 9.9640449 | BH37: 9.9640449 | BI37: 9.9640449 | BJ37: 9.9640449 | BK37: 9.9640449 | BL37: 9.9640449 | BM37: 9.9640449 | BN37: 9.9640449
D38: 河北 | E38: =1/ABS(E5) -> 0.19119403 | F38: =1/ABS(F5) -> 0.24039027 | G38: 0 | H38: =1/ABS(H5) -> 3.3180151 | I38: =1/ABS(I5) -> 0.70035564 | J38: =1/ABS(J5) -> 0.94171786 | K38: =1/ABS(K5) -> 3.2369038 | L38: =1/ABS(L5) -> 6.1410696 | M38: =1/ABS(M5) -> 0.17916165 | N38: =1/ABS(N5) -> 0.32634187 | O38: =1/ABS(O5) -> 0.37973581 | ... AI38: =1/ABS(AI5) -> 11.730494 | AJ38: =SUM(E38:AI38) -> 115.5812 | AK38: 115.5812 | AL38: 115.5812 | AM38: 115.5812 | AN38: 115.5812 | AO38: 115.5812 | AP38: 115.5812 | AQ38: 115.5812 | AR38: 115.5812 | AS38: 115.5812 | AT38: 115.5812 | AU38: 115.5812 | AV38: 115.5812 | AW38: 115.5812 | AX38: 115.5812 | AY38: 115.5812 | AZ38: 115.5812 | BA38: 115.5812 | BB38: 115.5812 | BC38: 115.5812 | BD38: 115.5812 | BE38: 115.5812 | BF38: 115.5812 | BG38: 115.5812 | BH38: 115.5812 | BI38: 115.5812 | BJ38: 115.5812 | BK38: 115.5812 | BL38: 115.5812 | BM38: 115.5812 | BN38: 115.5812
D39: 山西 | E39: =1/ABS(E6) -> 0.1807771 | F39: =1/ABS(F6) -> 0.22415056 | G39: =1/ABS(G6) -> 3.3180151 | H39: 0 | I39: =1/ABS(I6) -> 0.57829174 | J39: =1/ABS(J6) -> 0.73352816 | K39: =1/ABS(K6) -> 1.6384788 | L39: =1/ABS(L6) -> 7.217771 | M39: =1/ABS(M6) -> 0.16998313 | N39: =1/ABS(N6) -> 0.29711888 | O39: =1/ABS(O6) -> 0.34073932 | P39: =1/ABS(P6) -> 17.397942 | ... AI39: =1/ABS(AI6) -> 4.6266927 | AJ39: =SUM(E39:AI39) -> 125.73026 | AK39: 125.73026 | AL39: 125.73026 | AM39: 125.73026 | AN39: 125.73026 | AO39: 125.73026 | AP39: 125.73026 | AQ39: 125.73026 | AR39: 125.73026 | AS39: 125.73026 | AT39: 125.73026 | AU39: 125.73026 | AV39: 125.73026 | AW39: 125.73026 | AX39: 125.73026 | AY39: 125.73026 | AZ39: 125.73026 | BA39: 125.73026 | BB39: 125.73026 | BC39: 125.73026 | BD39: 125.73026 | BE39: 125.73026 | BF39: 125.73026 | BG39: 125.73026 | BH39: 125.73026 | BI39: 125.73026 | BJ39: 125.73026 | BK39: 125.73026 | BL39: 125.73026 | BM39: 125.73026 | BN39: 125.73026
D40: 内蒙古 | E40: =1/ABS(E7) -> 0.26298882 | F40: =1/ABS(F7) -> 0.3660247 | G40: =1/ABS(G7) -> 0.70035564 | H40: =1/ABS(H7) -> 0.57829174 | I40: 0 | J40: =1/ABS(J7) -> 2.7325628 | K40: =1/ABS(K7) -> 0.89372789 | L40: =1/ABS(L7) -> 0.62866034 | M40: =1/ABS(M7) -> 0.24074888 | N40: =1/ABS(N7) -> 0.61108811 | O40: =1/ABS(O7) -> 0.82948741 | P40: =1/ABS(P7) -> 0.55968821 | Q40: =1/ABS(Q7) -> 2.2443305 | ... AI40: =1/ABS(AI7) -> 0.66089752 | AJ40: =SUM(E40:AI40) -> 40.738286 | AK40: 40.738286 | AL40: 40.738286 | AM40: 40.738286 | AN40: 40.738286 | AO40: 40.738286 | AP40: 40.738286 | AQ40: 40.738286 | AR40: 40.738286 | AS40: 40.738286 | AT40: 40.738286 | AU40: 40.738286 | AV40: 40.738286 | AW40: 40.738286 | AX40: 40.738286 | AY40: 40.738286 | AZ40: 40.738286 | BA40: 40.738286 | BB40: 40.738286 | BC40: 40.738286 | BD40: 40.738286 | BE40: 40.738286 | BF40: 40.738286 | BG40: 40.738286 | BH40: 40.738286 | BI40: 40.738286 | BJ40: 40.738286 | BK40: 40.738286 | BL40: 40.738286 | BM40: 40.738286 | BN40: 40.738286
D41: 辽宁 | E41: =1/ABS(E8) -> 0.23990021 | F41: =1/ABS(F8) -> 0.32278755 | G41: =1/ABS(G8) -> 0.94171786 | H41: =1/ABS(H8) -> 0.73352816 | I41: =1/ABS(I8) -> 2.7325628 | J41: 0 | K41: =1/ABS(K8) -> 1.328106 | L41: =1/ABS(L8) -> 0.81650833 | M41: =1/ABS(M8) -> 0.22125545 | N41: =1/ABS(N8) -> 0.4994052 | O41: =1/ABS(O8) -> 0.63632636 | P41: =1/ABS(P8) -> 0.70385249 | Q41: =1/ABS(Q8) -> 1.2322494 | R41: =1/ABS(R8) -> 0.69094526 | ... AI41: =1/ABS(AI8) -> 0.87173541 | AJ41: =SUM(E41:AI41) -> 28.622628 | AK41: 28.622628 | AL41: 28.622628 | AM41: 28.622628 | AN41: 28.622628 | AO41: 28.622628 | AP41: 28.622628 | AQ41: 28.622628 | AR41: 28.622628 | AS41: 28.622628 | AT41: 28.622628 | AU41: 28.622628 | AV41: 28.622628 | AW41: 28.622628 | AX41: 28.622628 | AY41: 28.622628 | AZ41: 28.622628 | BA41: 28.622628 | BB41: 28.622628 | BC41: 28.622628 | BD41: 28.622628 | BE41: 28.622628 | BF41: 28.622628 | BG41: 28.622628 | BH41: 28.622628 | BI41: 28.622628 | BJ41: 28.622628 | BK41: 28.622628 | BL41: 28.622628 | BM41: 28.622628 | BN41: 28.622628
D42: 吉林 | E42: =1/ABS(E9) -> 0.2031962 | F42: =1/ABS(F9) -> 0.25967518 | G42: =1/ABS(G9) -> 3.2369038 | H42: =1/ABS(H9) -> 1.6384788 | I42: =1/ABS(I9) -> 0.89372789 | J42: =1/ABS(J9) -> 1.328106 | K42: 0 | L42: =1/ABS(L9) -> 2.1196532 | M42: =1/ABS(M9) -> 0.18965923 | N42: =1/ABS(N9) -> 0.3629324 | O42: =1/ABS(O9) -> 0.43020511 | P42: =1/ABS(P9) -> 1.4974537 | Q42: =1/ABS(Q9) -> 0.63919166 | R42: =1/ABS(R9) -> 1.4402152 | S42: =1/ABS(S9) -> 0.94049269 | ... AI42: =1/ABS(AI9) -> 2.5368793 | AJ42: =SUM(E42:AI42) -> 61.204463 | AK42: 61.204463 | AL42: 61.204463 | AM42: 61.204463 | AN42: 61.204463 | AO42: 61.204463 | AP42: 61.204463 | AQ42: 61.204463 | AR42: 61.204463 | AS42: 61.204463 | AT42: 61.204463 | AU42: 61.204463 | AV42: 61.204463 | AW42: 61.204463 | AX42: 61.204463 | AY42: 61.204463 | AZ42: 61.204463 | BA42: 61.204463 | BB42: 61.204463 | BC42: 61.204463 | BD42: 61.204463 | BE42: 61.204463 | BF42: 61.204463 | BG42: 61.204463 | BH42: 61.204463 | BI42: 61.204463 | BJ42: 61.204463 | BK42: 61.204463 | BL42: 61.204463 | BM42: 61.204463 | BN42: 61.204463
D43: 黑龙江 | E43: =1/ABS(E10) -> 0.18542118 | F43: =1/ABS(F10) -> 0.23133475 | G43: =1/ABS(G10) -> 6.1410696 | H43: =1/ABS(H10) -> 7.217771 | I43: =1/ABS(I10) -> 0.62866034 | J43: =1/ABS(J10) -> 0.81650833 | K43: =1/ABS(K10) -> 2.1196532 | L43: 0 | M43: =1/ABS(M10) -> 0.17408289 | N43: =1/ABS(N10) -> 0.30987485 | O43: =1/ABS(O10) -> 0.35762208 | P43: =1/ABS(P10) -> 5.1013904 | Q43: =1/ABS(Q10) -> 0.49109853 | R43: =1/ABS(R10) -> 4.4930612 | S43: =1/ABS(S10) -> 0.65144553 | T43: =1/ABS(T10) -> 152.46358 | ... AI43: =1/ABS(AI10) -> 12.888228 | AJ43: =SUM(E43:AI43) -> 269.84798 | AK43: 269.84798 | AL43: 269.84798 | AM43: 269.84798 | AN43: 269.84798 | AO43: 269.84798 | AP43: 269.84798 | AQ43: 269.84798 | AR43: 269.84798 | AS43: 269.84798 | AT43: 269.84798 | AU43: 269.84798 | AV43: 269.84798 | AW43: 269.84798 | AX43: 269.84798 | AY43: 269.84798 | AZ43: 269.84798 | BA43: 269.84798 | BB43: 269.84798 | BC43: 269.84798 | BD43: 269.84798 | BE43: 269.84798 | BF43: 269.84798 | BG43: 269.84798 | BH43: 269.84798 | BI43: 269.84798 | BJ43: 269.84798 | BK43: 269.84798 | BL43: 269.84798 | BM43: 269.84798 | BN43: 269.84798
D44: 上海 | E44: =1/ABS(E11) -> 2.8468714 | F44: =1/ABS(F11) -> 0.70340817 | G44: =1/ABS(G11) -> 0.17916165 | H44: =1/ABS(H11) -> 0.16998313 | I44: =1/ABS(I11) -> 0.24074888 | J44: =1/ABS(J11) -> 0.22125545 | K44: =1/ABS(K11) -> 0.18965923 | L44: =1/ABS(L11) -> 0.17408289 | M44: 0 | N44: =1/ABS(N11) -> 0.3972541 | O44: =1/ABS(O11) -> 0.33919669 | P44: =1/ABS(P11) -> 0.16833841 | Q44: =1/ABS(Q11) -> 0.26967708 | R44: =1/ABS(R11) -> 0.16758966 | S44: =1/ABS(S11) -> 0.23756682 | T44: =1/ABS(T11) -> 0.17388435 | U44: =1/ABS(U11) -> 0.1966783 | ... AI44: =1/ABS(AI11) -> 0.17646645 | AJ44: =SUM(E44:AI44) -> 9.1599654 | AK44: 9.1599654 | AL44: 9.1599654 | AM44: 9.1599654 | AN44: 9.1599654 | AO44: 9.1599654 | AP44: 9.1599654 | AQ44: 9.1599654 | AR44: 9.1599654 | AS44: 9.1599654 | AT44: 9.1599654 | AU44: 9.1599654 | AV44: 9.1599654 | AW44: 9.1599654 | AX44: 9.1599654 | AY44: 9.1599654 | AZ44: 9.1599654 | BA44: 9.1599654 | BB44: 9.1599654 | BC44: 9.1599654 | BD44: 9.1599654 | BE44: 9.1599654 | BF44: 9.1599654 | BG44: 9.1599654 | BH44: 9.1599654 | BI44: 9.1599654 | BJ44: 9.1599654 | BK44: 9.1599654 | BL44: 9.1599654 | BM44: 9.1599654 | BN44: 9.1599654
D45: 江苏 | E45: =1/ABS(E12) -> 0.46167674 | F45: =1/ABS(F12) -> 0.91271618 | G45: =1/ABS(G12) -> 0.32634187 | H45: =1/ABS(H12) -> 0.29711888 | I45: =1/ABS(I12) -> 0.61108811 | J45: =1/ABS(J12) -> 0.4994052 | K45: =1/ABS(K12) -> 0.3629324 | L45: =1/ABS(L12) -> 0.30987485 | M45: =1/ABS(M12) -> 0.3972541 | N45: 0 | O45: =1/ABS(O12) -> 2.3209319 | P45: =1/ABS(P12) -> 0.29212994 | Q45: =1/ABS(Q12) -> 0.83973065 | R45: =1/ABS(R12) -> 0.2898824 | S45: =1/ABS(S12) -> 0.59099505 | T45: =1/ABS(T12) -> 0.30924632 | U45: =1/ABS(U12) -> 0.38953484 | V45: =1/ABS(V12) -> 0.32115504 | ... AI45: =1/ABS(AI12) -> 0.31750879 | AJ45: =SUM(E45:AI45) -> 13.998978 | AK45: 13.998978 | AL45: 13.998978 | AM45: 13.998978 | AN45: 13.998978 | AO45: 13.998978 | AP45: 13.998978 | AQ45: 13.998978 | AR45: 13.998978 | AS45: 13.998978 | AT45: 13.998978 | AU45: 13.998978 | AV45: 13.998978 | AW45: 13.998978 | AX45: 13.998978 | AY45: 13.998978 | AZ45: 13.998978 | BA45: 13.998978 | BB45: 13.998978 | BC45: 13.998978 | BD45: 13.998978 | BE45: 13.998978 | BF45: 13.998978 | BG45: 13.998978 | BH45: 13.998978 | BI45: 13.998978 | BJ45: 13.998978 | BK45: 13.998978 | BL45: 13.998978 | BM45: 13.998978 | BN45: 13.998978
D46: 浙江 | E46: =1/ABS(E13) -> 0.3850776 | F46: =1/ABS(F13) -> 0.65509667 | G46: =1/ABS(G13) -> 0.37973581 | H46: =1/ABS(H13) -> 0.34073932 | I46: =1/ABS(I13) -> 0.82948741 | J46: =1/ABS(J13) -> 0.63632636 | K46: =1/ABS(K13) -> 0.43020511 | L46: =1/ABS(L13) -> 0.35762208 | ... N46: =1/ABS(N13) -> 2.3209319 | O46: 0 | P46: =1/ABS(P13) -> 0.33419412 | Q46: =1/ABS(Q13) -> 1.3157953 | R46: =1/ABS(R13) -> 0.33125599 | S46: =1/ABS(S13) -> 0.79289558 | T46: =1/ABS(T13) -> 0.3567852 | U46: =1/ABS(U13) -> 0.46809838 | V46: =1/ABS(V13) -> 0.37273107 | W46: =1/ABS(W13) -> 1.4572474 | ... AI46: =1/ABS(AI13) -> 0.36782858 | AJ46: =SUM(E46:AI46) -> 16.214991 | AK46: 16.214991 | AL46: 16.214991 | AM46: 16.214991 | AN46: 16.214991 | AO46: 16.214991 | AP46: 16.214991 | AQ46: 16.214991 | AR46: 16.214991 | AS46: 16.214991 | AT46: 16.214991 | AU46: 16.214991 | AV46: 16.214991 | AW46: 16.214991 | AX46: 16.214991 | AY46: 16.214991 | AZ46: 16.214991 | BA46: 16.214991 | BB46: 16.214991 | BC46: 16.214991 | BD46: 16.214991 | BE46: 16.214991 | BF46: 16.214991 | BG46: 16.214991 | BH46: 16.214991 | BI46: 16.214991 | BJ46: 16.214991 | BK46: 16.214991 | BL46: 16.214991 | BM46: 16.214991 | BN46: 16.214991
D47: 安徽 | E47: =1/ABS(E14) -> 0.17891802 | F47: =1/ABS(F14) -> 0.2212994 | G47: =1/ABS(G14) -> 2.7865782 | H47: =1/ABS(H14) -> 17.397942 | I47: =1/ABS(I14) -> 0.55968821 | J47: =1/ABS(J14) -> 0.70385249 | K47: =1/ABS(K14) -> 1.4974537 | L47: =1/ABS(L14) -> 5.1013904 | ... O47: =1/ABS(O14) -> 0.33419412 | P47: 0 | Q47: =1/ABS(Q14) -> 0.44797323 | R47: =1/ABS(R14) -> 37.678382 | S47: =1/ABS(S14) -> 0.57767647 | T47: =1/ABS(T14) -> 5.2779905 | U47: =1/ABS(U14) -> 1.1682655 | V47: =1/ABS(V14) -> 3.2323401 | W47: =1/ABS(W14) -> 0.4336424 | X47: =1/ABS(X14) -> 3.8290668 | ... AI47: =1/ABS(AI14) -> 3.6547681 | AJ47: =SUM(E47:AI47) -> 205.3891 | AK47: 205.3891 | AL47: 205.3891 | AM47: 205.3891 | AN47: 205.3891 | AO47: 205.3891 | AP47: 205.3891 | AQ47: 205.3891 | AR47: 205.3891 | AS47: 205.3891 | AT47: 205.3891 | AU47: 205.3891 | AV47: 205.3891 | AW47: 205.3891 | AX47: 205.3891 | AY47: 205.3891 | AZ47: 205.3891 | BA47: 205.3891 | BB47: 205.3891 | BC47: 205.3891 | BD47: 205.3891 | BE47: 205.3891 | BF47: 205.3891 | BG47: 205.3891 | BH47: 205.3891 | BI47: 205.3891 | BJ47: 205.3891 | BK47: 205.3891 | BL47: 205.3891 | BM47: 205.3891 | BN47: 205.3891
D48: 福建 | E48: =1/ABS(E15) -> 0.29789604 | F48: =1/ABS(F15) -> 0.43735178 | G48: =1/ABS(G15) -> 0.53378508 | H48: =1/ABS(H15) -> 0.45981278 | I48: =1/ABS(I15) -> 2.2443305 | J48: =1/ABS(J15) -> 1.2322494 | K48: =1/ABS(K15) -> 0.63919166 | L48: =1/ABS(L15) -> 0.49109853 | ... P48: =1/ABS(P15) -> 0.44797323 | Q48: 0 | R48: =1/ABS(R15) -> 0.44270968 | S48: =1/ABS(S15) -> 1.9951976 | T48: =1/ABS(T15) -> 0.48952174 | U48: =1/ABS(U15) -> 0.72658237 | V48: =1/ABS(V15) -> 0.52004707 | W48: =1/ABS(W15) -> 13.555399 | X48: =1/ABS(X15) -> 0.40105293 | Y48: =1/ABS(Y15) -> 0.50006736 | ... AI48: =1/ABS(AI15) -> 0.51055285 | AJ48: =SUM(E48:AI48) -> 32.573439 | AK48: 32.573439 | AL48: 32.573439 | AM48: 32.573439 | AN48: 32.573439 | AO48: 32.573439 | AP48: 32.573439 | AQ48: 32.573439 | AR48: 32.573439 | AS48: 32.573439 | AT48: 32.573439 | AU48: 32.573439 | AV48: 32.573439 | AW48: 32.573439 | AX48: 32.573439 | AY48: 32.573439 | AZ48: 32.573439 | BA48: 32.573439 | BB48: 32.573439 | BC48: 32.573439 | BD48: 32.573439 | BE48: 32.573439 | BF48: 32.573439 | BG48: 32.573439 | BH48: 32.573439 | BI48: 32.573439 | BJ48: 32.573439 | BK48: 32.573439 | BL48: 32.573439 | BM48: 32.573439 | BN48: 32.573439
D49: 江西 | E49: =1/ABS(E16) -> 0.17807243 | F49: =1/ABS(F16) -> 0.22000721 | G49: =1/ABS(G16) -> 2.5946833 | H49: =1/ABS(H16) -> 11.902143 | I49: =1/ABS(I16) -> 0.55149609 | J49: =1/ABS(J16) -> 0.69094526 | K49: =1/ABS(K16) -> 1.4402152 | L49: =1/ABS(L16) -> 4.4930612 | ... Q49: =1/ABS(Q16) -> 0.44270968 | R49: 0 | S49: =1/ABS(S16) -> 0.56895341 | T49: =1/ABS(T16) -> 4.6294911 | U49: =1/ABS(U16) -> 1.1331314 | V49: =1/ABS(V16) -> 2.9769542 | W49: =1/ABS(W16) -> 0.42870837 | X49: =1/ABS(X16) -> 4.2622144 | Y49: =1/ABS(Y16) -> 3.8597212 | Z49: =1/ABS(Z16) -> 1.1493072 | ... AI49: =1/ABS(AI16) -> 3.3316055 | AJ49: =SUM(E49:AI49) -> 130.62176 | AK49: 130.62176 | AL49: 130.62176 | AM49: 130.62176 | AN49: 130.62176 | AO49: 130.62176 | AP49: 130.62176 | AQ49: 130.62176 | AR49: 130.62176 | AS49: 130.62176 | AT49: 130.62176 | AU49: 130.62176 | AV49: 130.62176 | AW49: 130.62176 | AX49: 130.62176 | AY49: 130.62176 | AZ49: 130.62176 | BA49: 130.62176 | BB49: 130.62176 | BC49: 130.62176 | BD49: 130.62176 | BE49: 130.62176 | BF49: 130.62176 | BG49: 130.62176 | BH49: 130.62176 | BI49: 130.62176 | BJ49: 130.62176 | BK49: 130.62176 | BL49: 130.62176 | BM49: 130.62176 | BN49: 130.62176
D50: 山东 | E50: =1/ABS(E17) -> 0.25919633 | F50: =1/ABS(F17) -> 0.35871964 | G50: =1/ABS(G17) -> 0.7287516 | H50: =1/ABS(H17) -> 0.59751624 | I50: =1/ABS(I17) -> 17.973871 | J50: =1/ABS(J17) -> 3.2224747 | K50: =1/ABS(K17) -> 0.94049269 | L50: =1/ABS(L17) -> 0.65144553 | ... R50: =1/ABS(R17) -> 0.56895341 | S50: 0 | T50: =1/ABS(T17) -> 0.64867388 | U50: =1/ABS(U17) -> 1.1427227 | V50: =1/ABS(V17) -> 0.70338359 | W50: =1/ABS(W17) -> 1.7392066 | X50: =1/ABS(X17) -> 0.50194932 | Y50: =1/ABS(Y17) -> 0.66732193 | Z50: =1/ABS(Z17) -> 1.1267303 | AA50: =1/ABS(AA17) -> 0.5813123 | ... AI50: =1/ABS(AI17) -> 0.68612632 | AJ50: =SUM(E50:AI50) -> 41.270566 | AK50: 41.270566 | AL50: 41.270566 | AM50: 41.270566 | AN50: 41.270566 | AO50: 41.270566 | AP50: 41.270566 | AQ50: 41.270566 | AR50: 41.270566 | AS50: 41.270566 | AT50: 41.270566 | AU50: 41.270566 | AV50: 41.270566 | AW50: 41.270566 | AX50: 41.270566 | AY50: 41.270566 | AZ50: 41.270566 | BA50: 41.270566 | BB50: 41.270566 | BC50: 41.270566 | BD50: 41.270566 | BE50: 41.270566 | BF50: 41.270566 | BG50: 41.270566 | BH50: 41.270566 | BI50: 41.270566 | BJ50: 41.270566 | BK50: 41.270566 | BL50: 41.270566 | BM50: 41.270566 | BN50: 41.270566
D51: 河南 | E51: =1/ABS(E18) -> 0.18519595 | F51: =1/ABS(F18) -> 0.23098427 | G51: =1/ABS(G18) -> 5.9032914 | H51: =1/ABS(H18) -> 7.5764472 | I51: =1/ABS(I18) -> 0.6260788 | J51: =1/ABS(J18) -> 0.81215886 | K51: =1/ABS(K18) -> 2.0905884 | L51: =1/ABS(L18) -> 152.46358 | ... S51: =1/ABS(S18) -> 0.64867388 | T51: 0 | U51: =1/ABS(U18) -> 1.5003666 | V51: =1/ABS(V18) -> 8.3397732 | W51: =1/ABS(W18) -> 0.47245995 | X51: =1/ABS(X18) -> 2.2191337 | Y51: =1/ABS(Y18) -> 23.212838 | Z51: =1/ABS(Z18) -> 1.5288582 | AA51: =1/ABS(AA18) -> 5.5978809 | AB51: =1/ABS(AB18) -> 1.202036 | ... AI51: =1/ABS(AI18) -> 11.883665 | AJ51: =SUM(E51:AI51) -> 265.40596 | AK51: 265.40596 | AL51: 265.40596 | AM51: 265.40596 | AN51: 265.40596 | AO51: 265.40596 | AP51: 265.40596 | AQ51: 265.40596 | AR51: 265.40596 | AS51: 265.40596 | AT51: 265.40596 | AU51: 265.40596 | AV51: 265.40596 | AW51: 265.40596 | AX51: 265.40596 | AY51: 265.40596 | AZ51: 265.40596 | BA51: 265.40596 | BB51: 265.40596 | BC51: 265.40596 | BD51: 265.40596 | BE51: 265.40596 | BF51: 265.40596 | BG51: 265.40596 | BH51: 265.40596 | BI51: 265.40596 | BJ51: 265.40596 | BK51: 265.40596 | BL51: 265.40596 | BM51: 265.40596 | BN51: 265.40596
D52: 湖北 | E52: =1/ABS(E19) -> 0.21127435 | F52: =1/ABS(F19) -> 0.27301553 | G52: =1/ABS(G19) -> 2.0116404 | H52: =1/ABS(H19) -> 1.2523611 | I52: =1/ABS(I19) -> 1.0744148 | J52: =1/ABS(J19) -> 1.7705933 | K52: =1/ABS(K19) -> 5.3143567 | L52: =1/ABS(L19) -> 1.5152782 | ... T52: =1/ABS(T19) -> 1.5003666 | U52: 0 | V52: =1/ABS(V19) -> 1.8295034 | W52: =1/ABS(W19) -> 0.68961818 | X52: =1/ABS(X19) -> 0.89515093 | Y52: =1/ABS(Y19) -> 1.6040444 | Z52: =1/ABS(Z19) -> 80.509711 | AA52: =1/ABS(AA19) -> 1.183232 | AB52: =1/ABS(AB19) -> 0.66736715 | AC52: =1/ABS(AC19) -> 0.74896746 | ... AI52: =1/ABS(AI19) -> 1.7171667 | AJ52: =SUM(E52:AI52) -> 118.5467 | AK52: 118.5467 | AL52: 118.5467 | AM52: 118.5467 | AN52: 118.5467 | AO52: 118.5467 | AP52: 118.5467 | AQ52: 118.5467 | AR52: 118.5467 | AS52: 118.5467 | AT52: 118.5467 | AU52: 118.5467 | AV52: 118.5467 | AW52: 118.5467 | AX52: 118.5467 | AY52: 118.5467 | AZ52: 118.5467 | BA52: 118.5467 | BB52: 118.5467 | BC52: 118.5467 | BD52: 118.5467 | BE52: 118.5467 | BF52: 118.5467 | BG52: 118.5467 | BH52: 118.5467 | BI52: 118.5467 | BJ52: 118.5467 | BK52: 118.5467 | BL52: 118.5467 | BM52: 118.5467 | BN52: 118.5467
D53: 湖南 | E53: =1/ABS(E20) -> 0.18940188 | F53: =1/ABS(F20) -> 0.23756401 | G53: =1/ABS(G20) -> 20.20623 | H53: =1/ABS(H20) -> 3.969903 | I53: =1/ABS(I20) -> 0.67689423 | J53: =1/ABS(J20) -> 0.89978318 | K53: =1/ABS(K20) -> 2.7899693 | L53: =1/ABS(L20) -> 8.822357 | ... U53: =1/ABS(U20) -> 1.8295034 | V53: 0 | W53: =1/ABS(W20) -> 0.50083283 | X53: =1/ABS(X20) -> 1.7527451 | Y53: =1/ABS(Y20) -> 13.016134 | Z53: =1/ABS(Z20) -> 1.8720437 | AA53: =1/ABS(AA20) -> 3.3495635 | AB53: =1/ABS(AB20) -> 1.0506087 | AC53: =1/ABS(AC20) -> 1.2681101 | AD53: =1/ABS(AD20) -> 1.6317162 | ... AI53: =1/ABS(AI20) -> 27.965604 | AJ53: =SUM(E53:AI53) -> 214.35109 | AK53: 214.35109 | AL53: 214.35109 | AM53: 214.35109 | AN53: 214.35109 | AO53: 214.35109 | AP53: 214.35109 | AQ53: 214.35109 | AR53: 214.35109 | AS53: 214.35109 | AT53: 214.35109 | AU53: 214.35109 | AV53: 214.35109 | AW53: 214.35109 | AX53: 214.35109 | AY53: 214.35109 | AZ53: 214.35109 | BA53: 214.35109 | BB53: 214.35109 | BC53: 214.35109 | BD53: 214.35109 | BE53: 214.35109 | BF53: 214.35109 | BG53: 214.35109 | BH53: 214.35109 | BI53: 214.35109 | BJ53: 214.35109 | BK53: 214.35109 | BL53: 214.35109 | BM53: 214.35109 | BN53: 214.35109
D54: 广东 | E54: =1/ABS(E21) -> 0.30458976 | F54: =1/ABS(F21) -> 0.45193296 | G54: =1/ABS(G21) -> 0.51356201 | H54: =1/ABS(H21) -> 0.44472719 | I54: =1/ABS(I21) -> 1.9255263 | J54: =1/ABS(J21) -> 1.1295665 | K54: =1/ABS(K21) -> 0.61040845 | L54: =1/ABS(L21) -> 0.47392857 | ... V54: =1/ABS(V21) -> 0.50083283 | W54: 0 | X54: =1/ABS(X21) -> 0.38952826 | Y54: =1/ABS(Y21) -> 0.48227589 | Z54: =1/ABS(Z21) -> 0.68376131 | AA54: =1/ABS(AA21) -> 0.43568797 | AB54: =1/ABS(AB21) -> 0.33915512 | AC54: =1/ABS(AC21) -> 0.35903429 | AD54: =1/ABS(AD21) -> 0.38321137 | AE54: =1/ABS(AE21) -> 0.5849916 | ... AI54: =1/ABS(AI21) -> 0.49202128 | AJ54: =SUM(E54:AI54) -> 31.738721 | AK54: 31.738721 | AL54: 31.738721 | AM54: 31.738721 | AN54: 31.738721 | AO54: 31.738721 | AP54: 31.738721 | AQ54: 31.738721 | AR54: 31.738721 | AS54: 31.738721 | AT54: 31.738721 | AU54: 31.738721 | AV54: 31.738721 | AW54: 31.738721 | AX54: 31.738721 | AY54: 31.738721 | AZ54: 31.738721 | BA54: 31.738721 | BB54: 31.738721 | BC54: 31.738721 | BD54: 31.738721 | BE54: 31.738721 | BF54: 31.738721 | BG54: 31.738721 | BH54: 31.738721 | BI54: 31.738721 | BJ54: 31.738721 | BK54: 31.738721 | BL54: 31.738721 | BM54: 31.738721 | BN54: 31.738721
D55: 广西 | E55: =1/ABS(E22) -> 0.17093105 | F55: =1/ABS(F22) -> 0.20920829 | G55: =1/ABS(G22) -> 1.6128426 | H55: =1/ABS(H22) -> 3.1383546 | I55: =1/ABS(I22) -> 0.48831241 | J55: =1/ABS(J22) -> 0.59456126 | K55: =1/ABS(K22) -> 1.076472 | L55: =1/ABS(L22) -> 2.1872973 | ... W55: =1/ABS(W22) -> 0.38952826 | X55: 0 | Y55: =1/ABS(Y22) -> 2.0254974 | Z55: =1/ABS(Z22) -> 0.90521562 | AA55: =1/ABS(AA22) -> 3.6766428 | AB55: =1/ABS(AB22) -> 2.6226377 | AC55: =1/ABS(AC22) -> 4.586284 | AD55: =1/ABS(AD22) -> 23.630574 | AE55: =1/ABS(AE22) -> 1.1657979 | AF55: =1/ABS(AF22) -> 2.0797499 | ... AI55: =1/ABS(AI22) -> 1.8699439 | AJ55: =SUM(E55:AI55) -> 71.430756 | AK55: 71.430756 | AL55: 71.430756 | AM55: 71.430756 | AN55: 71.430756 | AO55: 71.430756 | AP55: 71.430756 | AQ55: 71.430756 | AR55: 71.430756 | AS55: 71.430756 | AT55: 71.430756 | AU55: 71.430756 | AV55: 71.430756 | AW55: 71.430756 | AX55: 71.430756 | AY55: 71.430756 | AZ55: 71.430756 | BA55: 71.430756 | BB55: 71.430756 | BC55: 71.430756 | BD55: 71.430756 | BE55: 71.430756 | BF55: 71.430756 | BG55: 71.430756 | BH55: 71.430756 | BI55: 71.430756 | BJ55: 71.430756 | BK55: 71.430756 | BL55: 71.430756 | BM55: 71.430756 | BN55: 71.430756
D56: 海南 | E56: =1/ABS(E23) -> 0.18668536 | F56: =1/ABS(F23) -> 0.23330583 | G56: =1/ABS(G23) -> 7.9165647 | H56: =1/ABS(H23) -> 5.7120794 | I56: =1/ABS(I23) -> 0.64343298 | J56: =1/ABS(J23) -> 0.84160449 | K56: =1/ABS(K23) -> 2.2975058 | L56: =1/ABS(L23) -> 27.381757 | ... X56: =1/ABS(X23) -> 2.0254974 | Y56: 0 | Z56: =1/ABS(Z23) -> 1.6366524 | AA56: =1/ABS(AA23) -> 4.5102208 | AB56: =1/ABS(AB23) -> 1.1428553 | AC56: =1/ABS(AC23) -> 1.404993 | AD56: =1/ABS(AD23) -> 1.8655883 | AE56: =1/ABS(AE23) -> 2.7466816 | AF56: =1/ABS(AF23) -> 1.0261326 | AG56: =1/ABS(AG23) -> 8.3113168 | ... AI56: =1/ABS(AI23) -> 24.34896 | AJ56: =SUM(E56:AI56) -> 154.18996 | AK56: 154.18996 | AL56: 154.18996 | AM56: 154.18996 | AN56: 154.18996 | AO56: 154.18996 | AP56: 154.18996 | AQ56: 154.18996 | AR56: 154.18996 | AS56: 154.18996 | AT56: 154.18996 | AU56: 154.18996 | AV56: 154.18996 | AW56: 154.18996 | AX56: 154.18996 | AY56: 154.18996 | AZ56: 154.18996 | BA56: 154.18996 | BB56: 154.18996 | BC56: 154.18996 | BD56: 154.18996 | BE56: 154.18996 | BF56: 154.18996 | BG56: 154.18996 | BH56: 154.18996 | BI56: 154.18996 | BJ56: 154.18996 | BK56: 154.18996 | BL56: 154.18996 | BM56: 154.18996 | BN56: 154.18996
D57: 重庆 | E57: =1/ABS(E24) -> 0.21072137 | F57: =1/ABS(F24) -> 0.27209284 | G57: =1/ABS(G24) -> 2.063192 | H57: =1/ABS(H24) -> 1.2721499 | I57: =1/ABS(I24) -> 1.0602653 | J57: =1/ABS(J24) -> 1.7324918 | K57: =1/ABS(K24) -> 5.6899435 | L57: =1/ABS(L24) -> 1.5443444 | ... Y57: =1/ABS(Y24) -> 1.6366524 | Z57: 0 | AA57: =1/ABS(AA24) -> 1.2008811 | AB57: =1/ABS(AB24) -> 0.67294538 | AC57: =1/ABS(AC24) -> 0.7560004 | AD57: =1/ABS(AD24) -> 0.87181888 | AE57: =1/ABS(AE24) -> 4.0497702 | AF57: =1/ABS(AF24) -> 0.63070146 | AG57: =1/ABS(AG24) -> 1.3673883 | AH57: =1/ABS(AH24) -> 1.9092071 | AI57: =1/ABS(AI24) -> 1.7545898 | AJ57: =SUM(E57:AI57) -> 119.42559 | AK57: 119.42559 | AL57: 119.42559 | AM57: 119.42559 | AN57: 119.42559 | AO57: 119.42559 | AP57: 119.42559 | AQ57: 119.42559 | AR57: 119.42559 | AS57: 119.42559 | AT57: 119.42559 | AU57: 119.42559 | AV57: 119.42559 | AW57: 119.42559 | AX57: 119.42559 | AY57: 119.42559 | AZ57: 119.42559 | BA57: 119.42559 | BB57: 119.42559 | BC57: 119.42559 | BD57: 119.42559 | BE57: 119.42559 | BF57: 119.42559 | BG57: 119.42559 | BH57: 119.42559 | BI57: 119.42559 | BJ57: 119.42559 | BK57: 119.42559 | BL57: 119.42559 | BM57: 119.42559 | BN57: 119.42559
D58: 四川 | E58: =1/ABS(E25) -> 0.17926528 | F58: =1/ABS(F25) -> 0.22183091 | G58: =1/ABS(G25) -> 2.8732655 | H58: =1/ABS(H25) -> 21.435748 | I58: =1/ABS(I25) -> 0.56310046 | J58: =1/ABS(J25) -> 0.70925747 | K58: =1/ABS(K25) -> 1.522132 | L58: =1/ABS(L25) -> 5.3996272 | ... Z58: =1/ABS(Z25) -> 1.2008811 | AA58: 0 | AB58: =1/ABS(AB25) -> 1.5307307 | AC58: =1/ABS(AC25) -> 2.0406968 | AD58: =1/ABS(AD25) -> 3.1816197 | AE58: =1/ABS(AE25) -> 1.7070838 | AF58: =1/ABS(AF25) -> 1.3283488 | AG58: =1/ABS(AG25) -> 9.8618591 | AH58: =1/ABS(AH25) -> 3.2368298 | AI58: =1/ABS(AI25) -> 3.8053466 | AJ58: =SUM(E58:AI58) -> 200.50223 | AK58: 200.50223 | AL58: 200.50223 | AM58: 200.50223 | AN58: 200.50223 | AO58: 200.50223 | AP58: 200.50223 | AQ58: 200.50223 | AR58: 200.50223 | AS58: 200.50223 | AT58: 200.50223 | AU58: 200.50223 | AV58: 200.50223 | AW58: 200.50223 | AX58: 200.50223 | AY58: 200.50223 | AZ58: 200.50223 | BA58: 200.50223 | BB58: 200.50223 | BC58: 200.50223 | BD58: 200.50223 | BE58: 200.50223 | BF58: 200.50223 | BG58: 200.50223 | BH58: 200.50223 | BI58: 200.50223 | BJ58: 200.50223 | BK58: 200.50223 | BL58: 200.50223 | BM58: 200.50223 | BN58: 200.50223
D59: 贵州 | E59: =1/ABS(E26) -> 0.16047223 | F59: =1/ABS(F26) -> 0.19375261 | G59: =1/ABS(G26) -> 0.9986829 | H59: =1/ABS(H26) -> 1.4287065 | I59: =1/ABS(I26) -> 0.41166412 | J59: =1/ABS(J26) -> 0.48468211 | K59: =1/ABS(K26) -> 0.76320961 | L59: =1/ABS(L26) -> 1.1926332 | ... AA59: =1/ABS(AA26) -> 1.5307307 | AB59: 0 | AC59: =1/ABS(AC26) -> 6.1254213 | AD59: =1/ABS(AD26) -> 2.9500486 | AE59: =1/ABS(AE26) -> 0.80705228 | AF59: =1/ABS(AF26) -> 10.047069 | AG59: =1/ABS(AG26) -> 1.3250587 | AH59: =1/ABS(AH26) -> 1.0392558 | AI59: =1/ABS(AI26) -> 1.0916185 | AJ59: =SUM(E59:AI59) -> 42.869963 | AK59: 42.869963 | AL59: 42.869963 | AM59: 42.869963 | AN59: 42.869963 | AO59: 42.869963 | AP59: 42.869963 | AQ59: 42.869963 | AR59: 42.869963 | AS59: 42.869963 | AT59: 42.869963 | AU59: 42.869963 | AV59: 42.869963 | AW59: 42.869963 | AX59: 42.869963 | AY59: 42.869963 | AZ59: 42.869963 | BA59: 42.869963 | BB59: 42.869963 | BC59: 42.869963 | BD59: 42.869963 | BE59: 42.869963 | BF59: 42.869963 | BG59: 42.869963 | BH59: 42.869963 | BI59: 42.869963 | BJ59: 42.869963 | BK59: 42.869963 | BL59: 42.869963 | BM59: 42.869963 | BN59: 42.869963
...

Sheet 空间经济地理矩阵（非对称）
A1: 2000-2020年人均GDP差值 | E1: 北京 | F1: 天津 | G1: 河北 | H1: 山西 | I1: 内蒙古 | J1: 辽宁 | K1: 吉林 | L1: 黑龙江 | M1: 上海 | N1: 江苏 | O1: 浙江 | P1: 安徽 | Q1: 福建 | R1: 江西 | S1: 山东 | T1: 河南 | U1: 湖北 | V1: 湖南 | W1: 广东 | X1: 广西 | Y1: 海南 | Z1: 重庆 | AA1: 四川 | AB1: 贵州 | AC1: 云南 | AD1: 西藏 | AE1: 陕西 | AF1: 甘肃 | AG1: 青海 | AH1: 宁夏 | AI1: 新疆
C2: 不对称 | E2: 8.0755955 | F2: 7.0052086 | G2: 2.8453065 | H2: 2.5439215 | I2: 4.2731525 | J2: 3.9071957 | K2: 3.1542437 | L2: 2.6824684 | M2: 8.4268583 | N2: 5.9095777 | O2: 5.4787163 | P2: 2.4864434 | Q2: 4.7187197 | R2: 2.459903 | S2: 4.2175162 | T2: 2.6759095 | U2: 3.3424132 | V2: 2.7958168 | W2: 4.792491 | X2: 2.2252832 | Y2: 2.7189891 | Z2: 3.3299924 | AA2: 2.4972705 | AB2: 1.8439877 | AC2: 2.0072418 | AD2: 2.1829651 | AE2: 3.0830648 | AF2: 1.7444562 | AG2: 2.5986712 | AH2: 2.8062147 | AI2: 2.7600586
A3: 2000-2020 | B3: 8.0755955 | D3: 北京 | E3: =IF($B3=E$2,0,$B3/E$2) -> 0 | F3: =IF($B3=F$2,0,$B3/F$2) -> 1.1527987 | G3: =IF($B3=G$2,0,$B3/G$2) -> 2.8382164 | H3: =IF($B3=H$2,0,$B3/H$2) -> 3.1744672 | I3: =IF($B3=I$2,0,$B3/I$2) -> 1.8898449 | J3: =IF($B3=J$2,0,$B3/J$2) -> 2.0668521 | K3: =IF($B3=K$2,0,$B3/K$2) -> 2.5602319 | L3: =IF($B3=L$2,0,$B3/L$2) -> 3.010509 | ... AI3: =IF($B3=AI$2,0,$B3/AI$2) -> 2.9258783
A4: 2000-2020 | B4: 7.0052086 | D4: 天津 | E4: =IF($B4=E$2,0,$B4/E$2) -> 0.86745412 | F4: =IF($B4=F$2,0,$B4/F$2) -> 0 | G4: =IF($B4=G$2,0,$B4/G$2) -> 2.4620225 | H4: =IF($B4=H$2,0,$B4/H$2) -> 2.7537047 | I4: =IF($B4=I$2,0,$B4/I$2) -> 1.6393537 | J4: =IF($B4=J$2,0,$B4/J$2) -> 1.7928993 | K4: =IF($B4=K$2,0,$B4/K$2) -> 2.2208837 | L4: =IF($B4=L$2,0,$B4/L$2) -> 2.6114785 | ... AI4: =IF($B4=AI$2,0,$B4/AI$2) -> 2.5380652
A5: 2000-2020 | B5: 2.8453065 | D5: 河北 | E5: =IF($B5=E$2,0,$B5/E$2) -> 0.35233396 | F5: =IF($B5=F$2,0,$B5/F$2) -> 0.40617013 | G5: =IF($B5=G$2,0,$B5/G$2) -> 0 | H5: =IF($B5=H$2,0,$B5/H$2) -> 1.1184726 | I5: =IF($B5=I$2,0,$B5/I$2) -> 0.66585653 | J5: =IF($B5=J$2,0,$B5/J$2) -> 0.72822217 | K5: =IF($B5=K$2,0,$B5/K$2) -> 0.90205665 | L5: =IF($B5=L$2,0,$B5/L$2) -> 1.0607046 | ... AI5: =IF($B5=AI$2,0,$B5/AI$2) -> 1.0308863
A6: 2000-2020 | B6: 2.5439215 | D6: 山西 | E6: =IF($B6=E$2,0,$B6/E$2) -> 0.31501349 | F6: =IF($B6=F$2,0,$B6/F$2) -> 0.36314715 | G6: =IF($B6=G$2,0,$B6/G$2) -> 0.89407643 | H6: =IF($B6=H$2,0,$B6/H$2) -> 0 | I6: =IF($B6=I$2,0,$B6/I$2) -> 0.59532663 | J6: =IF($B6=J$2,0,$B6/J$2) -> 0.65108628 | K6: =IF($B6=K$2,0,$B6/K$2) -> 0.80650759 | L6: =IF($B6=L$2,0,$B6/L$2) -> 0.94835096 | ... AI6: =IF($B6=AI$2,0,$B6/AI$2) -> 0.92169112
A7: 2000-2020 | B7: 4.2731525 | D7: 内蒙古 | E7: =IF($B7=E$2,0,$B7/E$2) -> 0.52914395 | F7: =IF($B7=F$2,0,$B7/F$2) -> 0.60999647 | G7: =IF($B7=G$2,0,$B7/G$2) -> 1.501825 | H7: =IF($B7=H$2,0,$B7/H$2) -> 1.6797501 | I7: =IF($B7=I$2,0,$B7/I$2) -> 0 | J7: =IF($B7=J$2,0,$B7/J$2) -> 1.0936623 | K7: =IF($B7=K$2,0,$B7/K$2) -> 1.3547312 | L7: =IF($B7=L$2,0,$B7/L$2) -> 1.5929927 | ... AI7: =IF($B7=AI$2,0,$B7/AI$2) -> 1.5482108
A8: 2000-2020 | B8: 3.9071957 | D8: 辽宁 | E8: =IF($B8=E$2,0,$B8/E$2) -> 0.48382756 | F8: =IF($B8=F$2,0,$B8/F$2) -> 0.5577558 | G8: =IF($B8=G$2,0,$B8/G$2) -> 1.3732073 | H8: =IF($B8=H$2,0,$B8/H$2) -> 1.5358948 | I8: =IF($B8=I$2,0,$B8/I$2) -> 0.91435905 | J8: =IF($B8=J$2,0,$B8/J$2) -> 0 | K8: =IF($B8=K$2,0,$B8/K$2) -> 1.2387108 | L8: =IF($B8=L$2,0,$B8/L$2) -> 1.4565673 | ... AI8: =IF($B8=AI$2,0,$B8/AI$2) -> 1.4156205
A9: 2000-2020 | B9: 3.1542437 | D9: 吉林 | E9: =IF($B9=E$2,0,$B9/E$2) -> 0.39058961 | F9: =IF($B9=F$2,0,$B9/F$2) -> 0.4502712 | G9: =IF($B9=G$2,0,$B9/G$2) -> 1.1085778 | H9: =IF($B9=H$2,0,$B9/H$2) -> 1.2399139 | I9: =IF($B9=I$2,0,$B9/I$2) -> 0.73815379 | J9: =IF($B9=J$2,0,$B9/J$2) -> 0.80729095 | K9: =IF($B9=K$2,0,$B9/K$2) -> 0 | L9: =IF($B9=L$2,0,$B9/L$2) -> 1.1758736 | ... AI9: =IF($B9=AI$2,0,$B9/AI$2) -> 1.1428177
A10: 2000-2020 | B10: 2.6824684 | D10: 黑龙江 | E10: =IF($B10=E$2,0,$B10/E$2) -> 0.33216974 | F10: =IF($B10=F$2,0,$B10/F$2) -> 0.38292485 | G10: =IF($B10=G$2,0,$B10/G$2) -> 0.94276958 | H10: =IF($B10=H$2,0,$B10/H$2) -> 1.054462 | I10: =IF($B10=I$2,0,$B10/I$2) -> 0.62774928 | J10: =IF($B10=J$2,0,$B10/J$2) -> 0.68654571 | K10: =IF($B10=K$2,0,$B10/K$2) -> 0.85043157 | L10: =IF($B10=L$2,0,$B10/L$2) -> 0 | ... AI10: =IF($B10=AI$2,0,$B10/AI$2) -> 0.97188821
A11: 2000-2020 | B11: 8.4268583 | D11: 上海 | E11: =IF($B11=E$2,0,$B11/E$2) -> 1.0434968 | F11: =IF($B11=F$2,0,$B11/F$2) -> 1.2029418 | G11: =IF($B11=G$2,0,$B11/G$2) -> 2.9616698 | H11: =IF($B11=H$2,0,$B11/H$2) -> 3.3125465 | I11: =IF($B11=I$2,0,$B11/I$2) -> 1.9720472 | J11: =IF($B11=J$2,0,$B11/J$2) -> 2.1567536 | K11: =IF($B11=K$2,0,$B11/K$2) -> 2.6715939 | L11: =IF($B11=L$2,0,$B11/L$2) -> 3.1414566 | ... AI11: =IF($B11=AI$2,0,$B11/AI$2) -> 3.0531447
A12: 2000-2020 | B12: 5.9095777 | D12: 江苏 | E12: =IF($B12=E$2,0,$B12/E$2) -> 0.73178229 | F12: =IF($B12=F$2,0,$B12/F$2) -> 0.84359768 | G12: =IF($B12=G$2,0,$B12/G$2) -> 2.0769565 | H12: =IF($B12=H$2,0,$B12/H$2) -> 2.3230189 | I12: =IF($B12=I$2,0,$B12/I$2) -> 1.382955 | J12: =IF($B12=J$2,0,$B12/J$2) -> 1.5124857 | K12: =IF($B12=K$2,0,$B12/K$2) -> 1.8735324 | L12: =IF($B12=L$2,0,$B12/L$2) -> 2.2030372 | ... AI12: =IF($B12=AI$2,0,$B12/AI$2) -> 2.1411059
A13: 2000-2020 | B13: 5.4787163 | D13: 浙江 | E13: =IF($B13=E$2,0,$B13/E$2) -> 0.67842877 | F13: =IF($B13=F$2,0,$B13/F$2) -> 0.78209182 | G13: =IF($B13=G$2,0,$B13/G$2) -> 1.9255276 | H13: =IF($B13=H$2,0,$B13/H$2) -> 2.1536499 | I13: =IF($B13=I$2,0,$B13/I$2) -> 1.2821252 | J13: =IF($B13=J$2,0,$B13/J$2) -> 1.4022119 | K13: =IF($B13=K$2,0,$B13/K$2) -> 1.736935 | L13: =IF($B13=L$2,0,$B13/L$2) -> 2.042416 | ... AI13: =IF($B13=AI$2,0,$B13/AI$2) -> 1.985
A14: 2000-2020 | B14: 2.4864434 | D14: 安徽 | E14: =IF($B14=E$2,0,$B14/E$2) -> 0.30789599 | F14: =IF($B14=F$2,0,$B14/F$2) -> 0.3549421 | G14: =IF($B14=G$2,0,$B14/G$2) -> 0.87387543 | H14: =IF($B14=H$2,0,$B14/H$2) -> 0.97740573 | I14: =IF($B14=I$2,0,$B14/I$2) -> 0.58187566 | J14: =IF($B14=J$2,0,$B14/J$2) -> 0.63637546 | K14: =IF($B14=K$2,0,$B14/K$2) -> 0.78828514 | L14: =IF($B14=L$2,0,$B14/L$2) -> 0.92692365 | ... AI14: =IF($B14=AI$2,0,$B14/AI$2) -> 0.90086617
... A33: 2000-2020 | B33: 2.7600586 | D33: 新疆 | E33: =IF($B33=E$2,0,$B33/E$2) -> 0.34177772 | F33: =IF($B33=F$2,0,$B33/F$2) -> 0.39400092 | G33: =IF($B33=G$2,0,$B33/G$2) -> 0.97003912 | H33: =IF($B33=H$2,0,$B33/H$2) -> 1.0849622 | I33: =IF($B33=I$2,0,$B33/I$2) -> 0.64590688 | J33: =IF($B33=J$2,0,$B33/J$2) -> 0.70640399 | K33: =IF($B33=K$2,0,$B33/K$2) -> 0.87503023 | L33: =IF($B33=L$2,0,$B33/L$2) -> 1.0289249 | ... AI33: =IF($B33=AI$2,0,$B33/AI$2) -> 0
B35: 1/绝对值 | E35: 北京 | F35: 天津 | G35: 河北 | H35: 山西 | I35: 内蒙古 | J35: 辽宁 | K35: 吉林 | L35: 黑龙江 | M35: 上海 | N35: 江苏 | O35: 浙江 | P35: 安徽 | Q35: 福建 | R35: 江西 | S35: 山东 | T35: 河南 | U35: 湖北 | V35: 湖南 | W35: 广东 | X35: 广西 | Y35: 海南 | Z35: 重庆 | AA35: 四川 | AB35: 贵州 | AC35: 云南 | AD35: 西藏 | AE35: 陕西 | AF35: 甘肃 | AG35: 青海 | AH35: 宁夏 | AI35: 新疆 | AJ35: 1 | AK35: 2 | AL35: 3 | AM35: 4 | AN35: 5 | AO35: 6 | AP35: 7 | AQ35: 8 | AR35: 9 | AS35: 10 | AT35: 11 | AU35: 12 | AV35: 13 | AW35: 14 | AX35: 15 | AY35: 16 | AZ35: 17 | BA35: 18 | BB35: 19 | BC35: 20 | BD35: 21 | BE35: 22 | BF35: 23 | BG35: 24 | BH35: 25 | BI35: 26 | BJ35: 27 | BK35: 28 | BL35: 29 | BM35: 30 | BN35: 31
B36: 不对称 | D36: 北京 | E36: 0 | F36: =1/ABS(F3) -> 0.86745412 | G36: =1/ABS(G3) -> 0.35233396 | H36: =1/ABS(H3) -> 0.31501349 | I36: =1/ABS(I3) -> 0.52914395 | J36: =1/ABS(J3) -> 0.48382756 | K36: =1/ABS(K3) -> 0.39058961 | L36: =1/ABS(L3) -> 0.33216974 | M36: =1/ABS(M3) -> 1.0434968 | ... AI36: =1/ABS(AI3) -> 0.34177772 | AJ36: =SUM(E36:AI36) -> 12.818133 | AK36: =$AJ36 -> 12.818133 | AL36: =$AJ36 -> 12.818133 | AM36: =$AJ36 -> 12.818133 | AN36: =$AJ36 -> 12.818133 | AO36: =$AJ36 -> 12.818133 | AP36: =$AJ36 -> 12.818133 | AQ36: =$AJ36 -> 12.818133 | AR36: =$AJ36 -> 12.818133 | ... BN36: =$AJ36 -> 12.818133
D37: 天津 | E37: =1/ABS(E4) -> 1.1527987 | F37: 0 | G37: =1/ABS(G4) -> 0.40617013 | H37: =1/ABS(H4) -> 0.36314715 | I37: =1/ABS(I4) -> 0.60999647 | J37: =1/ABS(J4) -> 0.5577558 | K37: =1/ABS(K4) -> 0.4502712 | L37: =1/ABS(L4) -> 0.38292485 | M37: =1/ABS(M4) -> 1.2029418 | N37: =1/ABS(N4) -> 0.84359768 | ... AI37: =1/ABS(AI4) -> 0.39400092 | AJ37: =SUM(E37:AI37) -> 14.929526 | AK37: =$AJ37 -> 14.929526 | AL37: =$AJ37 -> 14.929526 | AM37: =$AJ37 -> 14.929526 | AN37: =$AJ37 -> 14.929526 | AO37: =$AJ37 -> 14.929526 | AP37: =$AJ37 -> 14.929526 | AQ37: =$AJ37 -> 14.929526 | AR37: =$AJ37 -> 14.929526 | ... BN37: =$AJ37 -> 14.929526
D38: 河北 | E38: =1/ABS(E5) -> 2.8382164 | F38: =1/ABS(F5) -> 2.4620225 | G38: 0 | H38: =1/ABS(H5) -> 0.89407643 | I38: =1/ABS(I5) -> 1.501825 | J38: =1/ABS(J5) -> 1.3732073 | K38: =1/ABS(K5) -> 1.1085778 | L38: =1/ABS(L5) -> 0.94276958 | M38: =1/ABS(M5) -> 2.9616698 | N38: =1/ABS(N5) -> 2.0769565 | O38: =1/ABS(O5) -> 1.9255276 | ... AI38: =1/ABS(AI5) -> 0.97003912 | AJ38: =SUM(E38:AI38) -> 38.218851 | AK38: =$AJ38 -> 38.218851 | AL38: =$AJ38 -> 38.218851 | AM38: =$AJ38 -> 38.218851 | AN38: =$AJ38 -> 38.218851 | AO38: =$AJ38 -> 38.218851 | AP38: =$AJ38 -> 38.218851 | AQ38: =$AJ38 -> 38.218851 | AR38: =$AJ38 -> 38.218851 | ... BN38: =$AJ38 -> 38.218851
D39: 山西 | E39: =1/ABS(E6) -> 3.1744672 | F39: =1/ABS(F6) -> 2.7537047 | G39: =1/ABS(G6) -> 1.1184726 | H39: 0 | I39: =1/ABS(I6) -> 1.6797501 | J39: =1/ABS(J6) -> 1.5358948 | K39: =1/ABS(K6) -> 1.2399139 | L39: =1/ABS(L6) -> 1.054462 | M39: =1/ABS(M6) -> 3.3125465 | N39: =1/ABS(N6) -> 2.3230189 | O39: =1/ABS(O6) -> 2.1536499 | P39: =1/ABS(P6) -> 0.97740573 | ... AI39: =1/ABS(AI6) -> 1.0849622 | AJ39: =SUM(E39:AI39) -> 42.865211 | AK39: =$AJ39 -> 42.865211 | AL39: =$AJ39 -> 42.865211 | AM39: =$AJ39 -> 42.865211 | AN39: =$AJ39 -> 42.865211 | AO39: =$AJ39 -> 42.865211 | AP39: =$AJ39 -> 42.865211 | AQ39: =$AJ39 -> 42.865211 | AR39: =$AJ39 -> 42.865211 | ... BN39: =$AJ39 -> 42.865211
D40: 内蒙古 | E40: =1/ABS(E7) -> 1.8898449 | F40: =1/ABS(F7) -> 1.6393537 | G40: =1/ABS(G7) -> 0.66585653 | H40: =1/ABS(H7) -> 0.59532663 | I40: 0 | J40: =1/ABS(J7) -> 0.91435905 | K40: =1/ABS(K7) -> 0.73815379 | L40: =1/ABS(L7) -> 0.62774928 | M40: =1/ABS(M7) -> 1.9720472 | N40: =1/ABS(N7) -> 1.382955 | O40: =1/ABS(O7) -> 1.2821252 | P40: =1/ABS(P7) -> 0.58187566 | Q40: =1/ABS(Q7) -> 1.1042713 | ... AI40: =1/ABS(AI7) -> 0.64590688 | AJ40: =SUM(E40:AI40) -> 25.114128 | AK40: =$AJ40 -> 25.114128 | AL40: =$AJ40 -> 25.114128 | AM40: =$AJ40 -> 25.114128 | AN40: =$AJ40 -> 25.114128 | AO40: =$AJ40 -> 25.114128 | AP40: =$AJ40 -> 25.114128 | AQ40: =$AJ40 -> 25.114128 | AR40: =$AJ40 -> 25.114128 | ... BN40: =$AJ40 -> 25.114128
D41: 辽宁 | E41: =1/ABS(E8) -> 2.0668521 | F41: =1/ABS(F8) -> 1.7928993 | G41: =1/ABS(G8) -> 0.72822217 | H41: =1/ABS(H8) -> 0.65108628 | I41: =1/ABS(I8) -> 1.0936623 | J41: 0 | K41: =1/ABS(K8) -> 0.80729095 | L41: =1/ABS(L8) -> 0.68654571 | M41: =1/ABS(M8) -> 2.1567536 | N41: =1/ABS(N8) -> 1.5124857 | O41: =1/ABS(O8) -> 1.4022119 | P41: =1/ABS(P8) -> 0.63637546 | Q41: =1/ABS(Q8) -> 1.2076999 | R41: =1/ABS(R8) -> 0.62958275 | ... AI41: =1/ABS(AI8) -> 0.70640399 | AJ41: =SUM(E41:AI41) -> 27.560037 | AK41: =$AJ41 -> 27.560037 | AL41: =$AJ41 -> 27.560037 | AM41: =$AJ41 -> 27.560037 | AN41: =$AJ41 -> 27.560037 | AO41: =$AJ41 -> 27.560037 | AP41: =$AJ41 -> 27.560037 | AQ41: =$AJ41 -> 27.560037 | AR41: =$AJ41 -> 27.560037 | ... BN41: =$AJ41 -> 27.560037
D42: 吉林 | E42: =1/ABS(E9) -> 2.5602319 | F42: =1/ABS(F9) -> 2.2208837 | G42: =1/ABS(G9) -> 0.90205665 | H42: =1/ABS(H9) -> 0.80650759 | I42: =1/ABS(I9) -> 1.3547312 | J42: =1/ABS(J9) -> 1.2387108 | K42: 0 | L42: =1/ABS(L9) -> 0.85043157 | M42: =1/ABS(M9) -> 2.6715939 | N42: =1/ABS(N9) -> 1.8735324 | O42: =1/ABS(O9) -> 1.736935 | P42: =1/ABS(P9) -> 0.78828514 | Q42: =1/ABS(Q9) -> 1.4959908 | R42: =1/ABS(R9) -> 0.77987094 | S42: =1/ABS(S9) -> 1.3370927 | ... AI42: =1/ABS(AI9) -> 0.87503023 | AJ42: =SUM(E42:AI42) -> 34.377626 | AK42: =$AJ42 -> 34.377626 | AL42: =$AJ42 -> 34.377626 | AM42: =$AJ42 -> 34.377626 | AN42: =$AJ42 -> 34.377626 | AO42: =$AJ42 -> 34.377626 | AP42: =$AJ42 -> 34.377626 | AQ42: =$AJ42 -> 34.377626 | AR42: =$AJ42 -> 34.377626 | ... BN42: =$AJ42 -> 34.377626
D43: 黑龙江 | E43: =1/ABS(E10) -> 3.010509 | F43: =1/ABS(F10) -> 2.6114785 | G43: =1/ABS(G10) -> 1.0607046 | H43: =1/ABS(H10) -> 0.94835096 | I43: =1/ABS(I10) -> 1.5929927 | J43: =1/ABS(J10) -> 1.4565673 | K43: =1/ABS(K10) -> 1.1758736 | L43: 0 | M43: =1/ABS(M10) -> 3.1414566 | N43: =1/ABS(N10) -> 2.2030372 | O43: =1/ABS(O10) -> 2.042416 | P43: =1/ABS(P10) -> 0.92692365 | Q43: =1/ABS(Q10) -> 1.7590961 | R43: =1/ABS(R10) -> 0.91702963 | S43: =1/ABS(S10) -> 1.5722519 | T43: =1/ABS(T10) -> 0.99755489 | ... AI43: =1/ABS(AI10) -> 1.0289249 | AJ43: =SUM(E43:AI43) -> 40.599615 | AK43: =$AJ43 -> 40.599615 | AL43: =$AJ43 -> 40.599615 | AM43: =$AJ43 -> 40.599615 | AN43: =$AJ43 -> 40.599615 | AO43: =$AJ43 -> 40.599615 | AP43: =$AJ43 -> 40.599615 | AQ43: =$AJ43 -> 40.599615 | AR43: =$AJ43 -> 40.599615 | ... BN43: =$AJ43 -> 40.599615
D44: 上海 | E44: =1/ABS(E11) -> 0.95831628 | F44: =1/ABS(F11) -> 0.83129541 | G44: =1/ABS(G11) -> 0.33764737 | H44: =1/ABS(H11) -> 0.30188255 | I44: =1/ABS(I11) -> 0.50708726 | J44: =1/ABS(J11) -> 0.46365983 | K44: =1/ABS(K11) -> 0.37430838 | L44: =1/ABS(L11) -> 0.31832367 | M44: 0 | N44: =1/ABS(N11) -> 0.70127888 | O44: =1/ABS(O11) -> 0.65014934 | P44: =1/ABS(P11) -> 0.29506174 | Q44: =1/ABS(Q11) -> 0.55996191 | R44: =1/ABS(R11) -> 0.29191223 | S44: =1/ABS(S11) -> 0.500485 | T44: =1/ABS(T11) -> 0.31754533 | U44: =1/ABS(U11) -> 0.39663812 | ... AI44: =1/ABS(AI11) -> 0.32753115 | AJ44: =SUM(E44:AI44) -> 12.242142 | AK44: =$AJ44 -> 12.242142 | AL44: =$AJ44 -> 12.242142 | AM44: =$AJ44 -> 12.242142 | AN44: =$AJ44 -> 12.242142 | AO44: =$AJ44 -> 12.242142 | AP44: =$AJ44 -> 12.242142 | AQ44: =$AJ44 -> 12.242142 | AR44: =$AJ44 -> 12.242142 | ... BN44: =$AJ44 -> 12.242142
D45: 江苏 | E45: =1/ABS(E12) -> 1.3665267 | F45: =1/ABS(F12) -> 1.1853992 | G45: =1/ABS(G12) -> 0.48147374 | H45: =1/ABS(H12) -> 0.43047433 | I45: =1/ABS(I12) -> 0.72308931 | J45: =1/ABS(J12) -> 0.66116326 | K45: =1/ABS(K12) -> 0.53375112 | L45: =1/ABS(L12) -> 0.4539188 | M45: =1/ABS(M12) -> 1.4259662 | N45: 0 | O45: =1/ABS(O12) -> 0.927091 | P45: =1/ABS(P12) -> 0.42074807 | Q45: =1/ABS(Q12) -> 0.79848678 | R45: =1/ABS(R12) -> 0.41625699 | S45: =1/ABS(S12) -> 0.71367471 | T45: =1/ABS(T12) -> 0.45280892 | U45: =1/ABS(U12) -> 0.56559257 | V45: =1/ABS(V12) -> 0.47309925 | ... AI45: =1/ABS(AI12) -> 0.46704836 | AJ45: =SUM(E45:AI45) -> 17.882847 | AK45: =$AJ45 -> 17.882847 | AL45: =$AJ45 -> 17.882847 | AM45: =$AJ45 -> 17.882847 | AN45: =$AJ45 -> 17.882847 | AO45: =$AJ45 -> 17.882847 | AP45: =$AJ45 -> 17.882847 | AQ45: =$AJ45 -> 17.882847 | AR45: =$AJ45 -> 17.882847 | ... BN45: =$AJ45 -> 17.882847
D46: 浙江 | E46: =1/ABS(E13) -> 1.4739941 | F46: =1/ABS(F13) -> 1.2786222 | G46: =1/ABS(G13) -> 0.51933817 | H46: =1/ABS(H13) -> 0.46432802 | I46: =1/ABS(I13) -> 0.77995506 | J46: =1/ABS(J13) -> 0.71315897 | K46: =1/ABS(K13) -> 0.57572678 | L46: =1/ABS(L13) -> 0.48961623 | ... N46: =1/ABS(N13) -> 1.0786428 | O46: 0 | P46: =1/ABS(P13) -> 0.45383687 | Q46: =1/ABS(Q13) -> 0.86128199 | R46: =1/ABS(R13) -> 0.44899259 | S46: =1/ABS(S13) -> 0.76980007 | T46: =1/ABS(T13) -> 0.48841906 | U46: =1/ABS(U13) -> 0.61007233 | V46: =1/ABS(V13) -> 0.51030509 | W46: =1/ABS(W13) -> 0.87474707 | ... AI46: =1/ABS(AI13) -> 0.50377834 | AJ46: =SUM(E46:AI46) -> 19.367846 | AK46: =$AJ46 -> 19.367846 | AL46: =$AJ46 -> 19.367846 | AM46: =$AJ46 -> 19.367846 | AN46: =$AJ46 -> 19.367846 | AO46: =$AJ46 -> 19.367846 | AP46: =$AJ46 -> 19.367846 | AQ46: =$AJ46 -> 19.367846 | AR46: =$AJ46 -> 19.367846 | ... BN46: =$AJ46 -> 19.367846
D47: 安徽 | E47: =1/ABS(E14) -> 3.2478501 | F47: =1/ABS(F14) -> 2.8173609 | G47: =1/ABS(G14) -> 1.1443279 | H47: =1/ABS(H14) -> 1.0231166 | I47: =1/ABS(I14) -> 1.7185802 | J47: =1/ABS(J14) -> 1.5713994 | K47: =1/ABS(K14) -> 1.2685765 | L47: =1/ABS(L14) -> 1.0788375 | ... O47: =1/ABS(O14) -> 2.2034349 | P47: 0 | Q47: =1/ABS(Q14) -> 1.8977788 | R47: =1/ABS(R14) -> 0.98932595 | S47: =1/ABS(S14) -> 1.6962044 | T47: =1/ABS(T14) -> 1.0761996 | U47: =1/ABS(U14) -> 1.3442547 | V47: =1/ABS(V14) -> 1.1244241 | W47: =1/ABS(W14) -> 1.9274482 | X47: =1/ABS(X14) -> 0.89496635 | ... AI47: =1/ABS(AI14) -> 1.1100428 | AJ47: =SUM(E47:AI47) -> 43.879224 | AK47: =$AJ47 -> 43.879224 | AL47: =$AJ47 -> 43.879224 | AM47: =$AJ47 -> 43.879224 | AN47: =$AJ47 -> 43.879224 | AO47: =$AJ47 -> 43.879224 | AP47: =$AJ47 -> 43.879224 | AQ47: =$AJ47 -> 43.879224 | AR47: =$AJ47 -> 43.879224 | ... BN47: =$AJ47 -> 43.879224
D48: 福建 | E48: =1/ABS(E15) -> 1.7113955 | F48: =1/ABS(F15) -> 1.4845571 | G48: =1/ABS(G15) -> 0.60298274 | H48: =1/ABS(H15) -> 0.53911266 | I48: =1/ABS(I15) -> 0.90557456 | J48: =1/ABS(J15) -> 0.8280203 | K48: =1/ABS(K15) -> 0.66845329 | L48: =1/ABS(L15) -> 0.56847378 | ... P48: =1/ABS(P15) -> 0.5269318 | Q48: 0 | R48: =1/ABS(R15) -> 0.5213073 | S48: =1/ABS(S15) -> 0.89378401 | T48: =1/ABS(T15) -> 0.5670838 | U48: =1/ABS(U15) -> 0.70833054 | V48: =1/ABS(V15) -> 0.59249479 | W48: =1/ABS(W15) -> 1.0156338 | X48: =1/ABS(X15) -> 0.47158622 | Y48: =1/ABS(Y15) -> 0.57621331 | ... AI48: =1/ABS(AI15) -> 0.58491684 | AJ48: =SUM(E48:AI48) -> 22.64829 | AK48: =$AJ48 -> 22.64829 | AL48: =$AJ48 -> 22.64829 | AM48: =$AJ48 -> 22.64829 | AN48: =$AJ48 -> 22.64829 | AO48: =$AJ48 -> 22.64829 | AP48: =$AJ48 -> 22.64829 | AQ48: =$AJ48 -> 22.64829 | AR48: =$AJ48 -> 22.64829 | ... BN48: =$AJ48 -> 22.64829
D49: 江西 | E49: =1/ABS(E16) -> 3.2828918 | F49: =1/ABS(F16) -> 2.847758 | G49: =1/ABS(G16) -> 1.1566743 | H49: =1/ABS(H16) -> 1.0341552 | I49: =1/ABS(I16) -> 1.7371223 | J49: =1/ABS(J16) -> 1.5883535 | K49: =1/ABS(K16) -> 1.2822634 | L49: =1/ABS(L16) -> 1.0904773 | ... Q49: =1/ABS(Q16) -> 1.9182544 | R49: 0 | S49: =1/ABS(S16) -> 1.7145051 | T49: =1/ABS(T16) -> 1.087811 | U49: =1/ABS(U16) -> 1.3587581 | V49: =1/ABS(V16) -> 1.1365557 | W49: =1/ABS(W16) -> 1.9482439 | X49: =1/ABS(X16) -> 0.90462233 | Y49: =1/ABS(Y16) -> 1.1053237 | Z49: =1/ABS(Z16) -> 1.3537088 | ... AI49: =1/ABS(AI16) -> 1.1220193 | AJ49: =SUM(E49:AI49) -> 44.363436 | AK49: =$AJ49 -> 44.363436 | AL49: =$AJ49 -> 44.363436 | AM49: =$AJ49 -> 44.363436 | AN49: =$AJ49 -> 44.363436 | AO49: =$AJ49 -> 44.363436 | AP49: =$AJ49 -> 44.363436 | AQ49: =$AJ49 -> 44.363436 | AR49: =$AJ49 -> 44.363436 | ... BN49: =$AJ49 -> 44.363436
D50: 山东 | E50: =1/ABS(E17) -> 1.9147752 | F50: =1/ABS(F17) -> 1.6609797 | G50: =1/ABS(G17) -> 0.67464033 | H50: =1/ABS(H17) -> 0.60318002 | I50: =1/ABS(I17) -> 1.0131917 | J50: =1/ABS(J17) -> 0.92642103 | K50: =1/ABS(K17) -> 0.74789131 | L50: =1/ABS(L17) -> 0.63603038 | ... R50: =1/ABS(R17) -> 0.5832587 | S50: 0 | T50: =1/ABS(T17) -> 0.63447521 | U50: =1/ABS(U17) -> 0.79250751 | V50: =1/ABS(V17) -> 0.66290601 | W50: =1/ABS(W17) -> 1.1363302 | X50: =1/ABS(X17) -> 0.52762885 | Y50: =1/ABS(Y17) -> 0.64468966 | Z50: =1/ABS(Z17) -> 0.78956244 | AA50: =1/ABS(AA17) -> 0.59211876 | ... AI50: =1/ABS(AI17) -> 0.65442751 | AJ50: =SUM(E50:AI50) -> 25.458619 | AK50: =$AJ50 -> 25.458619 | AL50: =$AJ50 -> 25.458619 | AM50: =$AJ50 -> 25.458619 | AN50: =$AJ50 -> 25.458619 | AO50: =$AJ50 -> 25.458619 | AP50: =$AJ50 -> 25.458619 | AQ50: =$AJ50 -> 25.458619 | AR50: =$AJ50 -> 25.458619 | ... BN50: =$AJ50 -> 25.458619
D51: 河南 | E51: =1/ABS(E18) -> 3.0178881 | F51: =1/ABS(F18) -> 2.6178795 | G51: =1/ABS(G18) -> 1.0633045 | H51: =1/ABS(H18) -> 0.95067547 | I51: =1/ABS(I18) -> 1.5968973 | J51: =1/ABS(J18) -> 1.4601375 | K51: =1/ABS(K18) -> 1.1787558 | L51: =1/ABS(L18) -> 1.0024511 | ... S51: =1/ABS(S18) -> 1.5761057 | T51: 0 | U51: =1/ABS(U18) -> 1.2490756 | V51: =1/ABS(V18) -> 1.0448099 | W51: =1/ABS(W18) -> 1.7909765 | X51: =1/ABS(X18) -> 0.83159883 | Y51: =1/ABS(Y18) -> 1.0160991 | Z51: =1/ABS(Z18) -> 1.2444339 | AA51: =1/ABS(AA18) -> 0.93324175 | AB51: =1/ABS(AB18) -> 0.68910689 | ... AI51: =1/ABS(AI18) -> 1.0314469 | AJ51: =SUM(E51:AI51) -> 40.70158 | AK51: =$AJ51 -> 40.70158 | AL51: =$AJ51 -> 40.70158 | AM51: =$AJ51 -> 40.70158 | AN51: =$AJ51 -> 40.70158 | AO51: =$AJ51 -> 40.70158 | AP51: =$AJ51 -> 40.70158 | AQ51: =$AJ51 -> 40.70158 | AR51: =$AJ51 -> 40.70158 | ... BN51: =$AJ51 -> 40.70158
D52: 湖北 | E52: =1/ABS(E19) -> 2.4160973 | F52: =1/ABS(F19) -> 2.0958535 | G52: =1/ABS(G19) -> 0.85127311 | H52: =1/ABS(H19) -> 0.76110323 | I52: =1/ABS(I19) -> 1.2784633 | J52: =1/ABS(J19) -> 1.1689745 | K52: =1/ABS(K19) -> 0.94370249 | L52: =1/ABS(L19) -> 0.80255439 | ... T52: =1/ABS(T19) -> 0.80059206 | U52: 0 | V52: =1/ABS(V19) -> 0.83646654 | W52: =1/ABS(W19) -> 1.4338416 | X52: =1/ABS(X19) -> 0.66577142 | Y52: =1/ABS(Y19) -> 0.81348083 | Z52: =1/ABS(Z19) -> 0.99628386 | AA52: =1/ABS(AA19) -> 0.74714593 | AB52: =1/ABS(AB19) -> 0.55169351 | AC52: =1/ABS(AC19) -> 0.60053668 | ... AI52: =1/ABS(AI19) -> 0.82576821 | AJ52: =SUM(E52:AI52) -> 32.385953 | AK52: =$AJ52 -> 32.385953 | AL52: =$AJ52 -> 32.385953 | AM52: =$AJ52 -> 32.385953 | AN52: =$AJ52 -> 32.385953 | AO52: =$AJ52 -> 32.385953 | AP52: =$AJ52 -> 32.385953 | AQ52: =$AJ52 -> 32.385953 | AR52: =$AJ52 -> 32.385953 | ... BN52: =$AJ52 -> 32.385953
D53: 湖南 | E53: =1/ABS(E20) -> 2.8884566 | F53: =1/ABS(F20) -> 2.5056036 | G53: =1/ABS(G20) -> 1.0177013 | H53: =1/ABS(H20) -> 0.90990278 | I53: =1/ABS(I20) -> 1.5284093 | J53: =1/ABS(J20) -> 1.3975149 | K53: =1/ABS(K20) -> 1.1282011 | L53: =1/ABS(L20) -> 0.95945786 | ... U53: =1/ABS(U20) -> 1.1955051 | V53: 0 | W53: =1/ABS(W20) -> 1.7141649 | X53: =1/ABS(X20) -> 0.79593312 | Y53: =1/ABS(Y20) -> 0.97252047 | Z53: =1/ABS(Z20) -> 1.1910624 | AA53: =1/ABS(AA20) -> 0.89321676 | AB53: =1/ABS(AB20) -> 0.65955239 | AC53: =1/ABS(AC20) -> 0.71794466 | AD53: =1/ABS(AD20) -> 0.78079691 | ... AI53: =1/ABS(AI20) -> 0.9872101 | AJ53: =SUM(E53:AI53) -> 38.913077 | AK53: =$AJ53 -> 38.913077 | AL53: =$AJ53 -> 38.913077 | AM53: =$AJ53 -> 38.913077 | AN53: =$AJ53 -> 38.913077 | AO53: =$AJ53 -> 38.913077 | AP53: =$AJ53 -> 38.913077 | AQ53: =$AJ53 -> 38.913077 | AR53: =$AJ53 -> 38.913077 | ... BN53: =$AJ53 -> 38.913077
D54: 广东 | E54: =1/ABS(E21) -> 1.6850518 | F54: =1/ABS(F21) -> 1.4617051 | G54: =1/ABS(G21) -> 0.59370096 | H54: =1/ABS(H21) -> 0.53081404 | I54: =1/ABS(I21) -> 0.89163495 | J54: =1/ABS(J21) -> 0.81527449 | K54: =1/ABS(K21) -> 0.65816372 | L54: =1/ABS(L21) -> 0.5597232 | ... V54: =1/ABS(V21) -> 0.58337445 | W54: 0 | X54: =1/ABS(X21) -> 0.46432705 | Y54: =1/ABS(Y21) -> 0.5673436 | Z54: =1/ABS(Z21) -> 0.69483539 | AA54: =1/ABS(AA21) -> 0.52107984 | AB54: =1/ABS(AB21) -> 0.38476602 | AC54: =1/ABS(AC21) -> 0.41883057 | AD54: =1/ABS(AD21) -> 0.45549697 | AE54: =1/ABS(AE21) -> 0.64331154 | ... AI54: =1/ABS(AI21) -> 0.57591315 | AJ54: =SUM(E54:AI54) -> 22.28427 | AK54: =$AJ54 -> 22.28427 | AL54: =$AJ54 -> 22.28427 | AM54: =$AJ54 -> 22.28427 | AN54: =$AJ54 -> 22.28427 | AO54: =$AJ54 -> 22.28427 | AP54: =$AJ54 -> 22.28427 | AQ54: =$AJ54 -> 22.28427 | AR54: =$AJ54 -> 22.28427 | ... BN54: =$AJ54 -> 22.28427
D55: 广西 | E55: =1/ABS(E22) -> 3.6290192 | F55: =1/ABS(F22) -> 3.1480077 | G55: =1/ABS(G22) -> 1.2786267 | H55: =1/ABS(H22) -> 1.14319 | I55: =1/ABS(I22) -> 1.9202736 | J55: =1/ABS(J22) -> 1.7558195 | K55: =1/ABS(K22) -> 1.4174572 | L55: =1/ABS(L22) -> 1.2054504 | ... W55: =1/ABS(W22) -> 2.1536544 | X55: 0 | Y55: =1/ABS(Y22) -> 1.2218621 | Z55: =1/ABS(Z22) -> 1.4964353 | AA55: =1/ABS(AA22) -> 1.1222259 | AB55: =1/ABS(AB22) -> 0.82865303 | AC55: =1/ABS(AC22) -> 0.90201632 | AD55: =1/ABS(AD22) -> 0.98098307 | AE55: =1/ABS(AE22) -> 1.3854708 | AF55: =1/ABS(AF22) -> 0.78392546 | ... AI55: =1/ABS(AI22) -> 1.2403179 | AJ55: =SUM(E55:AI55) -> 49.14627 | AK55: =$AJ55 -> 49.14627 | AL55: =$AJ55 -> 49.14627 | AM55: =$AJ55 -> 49.14627 | AN55: =$AJ55 -> 49.14627 | AO55: =$AJ55 -> 49.14627 | AP55: =$AJ55 -> 49.14627 | AQ55: =$AJ55 -> 49.14627 | AR55: =$AJ55 -> 49.14627 | ... BN55: =$AJ55 -> 49.14627
